Workbook

Sheet Absensi
A1: Data Karyawan
D2: =TEXT(D3,"mm") -> 01 | E2: =TEXT(E3,"mm") -> 01 | F2: =TEXT(F3,"mm") -> 01 | G2: =TEXT(G3,"mm") -> 01 | H2: =TEXT(H3,"mm") -> 01 | I2: =TEXT(I3,"mm") -> 01 | J2: =TEXT(J3,"mm") -> 01 | K2: =TEXT(K3,"mm") -> 01 | ... ND2: =TEXT(ND3,"mm") -> 12 | NE2: Batas
A3: No | B3: Lokasi | C3: Nama Karyawan | D3: 46023 | E3: 46024 | F3: 46025 | G3: 46026 | H3: 46027 | I3: 46028 | J3: 46029 | K3: 46030 | L3: 46031 | M3: 46032 | N3: 46033 | O3: 46034 | P3: 46035 | Q3: 46036 | R3: 46037 | S3: 46038 | T3: 46039 | U3: 46040 | V3: 46041 | W3: 46042 | X3: 46043 | Y3: 46044 | Z3: 46045 | AA3: 46046 | AB3: 46047 | AC3: 46048 | AD3: 46049 | AE3: 46050 | AF3: 46051 | AG3: 46052 | AH3: 46053 | AI3: 46054 | AJ3: 46055 | AK3: 46056 | AL3: 46057 | AM3: 46058 | AN3: 46059 | AO3: 46060 | AP3: 46061 | AQ3: 46062 | AR3: 46063 | AS3: 46064 | AT3: 46065 | AU3: 46066 | AV3: 46067 | AW3: 46068 | AX3: 46069 | AY3: 46070 | AZ3: 46071 | BA3: 46072 | BB3: 46073 | BC3: 46074 | BD3: 46075 | BE3: 46076 | BF3: 46077 | BG3: 46078 | BH3: 46079 | BI3: 46080 | BJ3: 46081 | BK3: 46082 | BL3: 46083 | BM3: 46084 | BN3: 46085 | BO3: 46086 | BP3: 46087 | BQ3: 46088 | BR3: 46089 | BS3: 46090 | BT3: 46091 | BU3: 46092 | BV3: 46093 | BW3: 46094 | BX3: 46095 | BY3: 46096 | BZ3: 46097 | CA3: 46098 | CB3: 46099 | CC3: 46100 | CD3: 46101 | CE3: 46102 | CF3: 46103 | CG3: 46104 | CH3: 46105 | CI3: 46106 | CJ3: 46107 | CK3: 46108 | CL3: 46109 | CM3: 46110 | CN3: 46111 | CO3: 46112 | CP3: 46113 | CQ3: 46114 | CR3: 46115 | CS3: 46116 | CT3: 46117 | CU3: 46118 | CV3: 46119 | CW3: 46120 | CX3: 46121 | CY3: 46122 | CZ3: 46123 | DA3: 46124 | DB3: 46125 | DC3: 46126 | DD3: 46127 | DE3: 46128 | DF3: 46129 | DG3: 46130 | DH3: 46131 | DI3: 46132 | DJ3: 46133 | DK3: 46134 | DL3: 46135 | DM3: 46136 | DN3: 46137 | DO3: 46138 | DP3: 46139 | DQ3: 46140 | DR3: 46141 | DS3: 46142 | DT3: 46143 | DU3: 46144 | DV3: 46145 | DW3: 46146 | DX3: 46147 | DY3: 46148 | DZ3: 46149 | EA3: 46150 | EB3: 46151 | EC3: 46152 | ED3: 46153 | EE3: 46154 | EF3: 46155 | EG3: 46156 | EH3: 46157 | EI3: 46158 | EJ3: 46159 | EK3: 46160 | EL3: 46161 | EM3: 46162 | EN3: 46163 | EO3: 46164 | EP3: 46165 | EQ3: 46166 | ER3: 46167 | ES3: 46168 | ET3: 46169 | EU3: 46170 | EV3: 46171 | EW3: 46172 | EX3: 46173 | EY3: 46174 | EZ3: 46175 | FA3: 46176 | FB3: 46177 | FC3: 46178 | FD3: 46179 | FE3: 46180 | FF3: 46181 | FG3: 46182 | FH3: 46183 | FI3: 46184 | FJ3: 46185 | FK3: 46186 | FL3: 46187 | FM3: 46188 | FN3: 46189 | FO3: 46190 | FP3: 46191 | FQ3: 46192 | FR3: 46193 | FS3: 46194 | FT3: 46195 | FU3: 46196 | FV3: 46197 | FW3: 46198 | FX3: 46199 | FY3: 46200 | FZ3: 46201 | GA3: 46202 | GB3: 46203 | GC3: 46204 | GD3: 46205 | GE3: 46206 | GF3: 46207 | GG3: 46208 | GH3: 46209 | GI3: 46210 | GJ3: 46211 | GK3: 46212 | GL3: 46213 | GM3: 46214 | GN3: 46215 | GO3: 46216 | GP3: 46217 | GQ3: 46218 | GR3: 46219 | GS3: 46220 | GT3: 46221 | GU3: 46222 | GV3: 46223 | GW3: 46224 | GX3: 46225 | GY3: 46226 | GZ3: 46227 | HA3: 46228 | HB3: 46229 | HC3: 46230 | HD3: 46231 | HE3: 46232 | HF3: 46233 | HG3: 46234 | HH3: 46235 | HI3: 46236 | HJ3: 46237 | HK3: 46238 | HL3: 46239 | HM3: 46240 | HN3: 46241 | HO3: 46242 | HP3: 46243 | HQ3: 46244 | HR3: 46245 | HS3: 46246 | HT3: 46247 | HU3: 46248 | HV3: 46249 | HW3: 46250 | HX3: 46251 | HY3: 46252 | HZ3: 46253 | IA3: 46254 | IB3: 46255 | IC3: 46256 | ID3: 46257 | IE3: 46258 | IF3: 46259 | IG3: 46260 | IH3: 46261 | II3: 46262 | IJ3: 46263 | IK3: 46264 | IL3: 46265 | IM3: 46266 | IN3: 46267 | IO3: 46268 | IP3: 46269 | IQ3: 46270 | IR3: 46271 | IS3: 46272 | IT3: 46273 | IU3: 46274 | IV3: 46275 | IW3: 46276 | IX3: 46277 | IY3: 46278 | IZ3: 46279 | JA3: 46280 | JB3: 46281 | JC3: 46282 | JD3: 46283 | JE3: 46284 | JF3: 46285 | JG3: 46286 | JH3: 46287 | JI3: 46288 | JJ3: 46289 | JK3: 46290 | JL3: 46291 | JM3: 46292 | JN3: 46293 | JO3: 46294 | JP3: 46295 | JQ3: 46296 | JR3: 46297 | JS3: 46298 | JT3: 46299 | JU3: 46300 | JV3: 46301 | JW3: 46302 | JX3: 46303 | JY3: 46304 | JZ3: 46305 | KA3: 46306 | KB3: 46307 | KC3: 46308 | KD3: 46309 | KE3: 46310 | KF3: 46311 | KG3: 46312 | KH3: 46313 | KI3: 46314 | KJ3: 46315 | KK3: 46316 | KL3: 46317 | KM3: 46318 | KN3: 46319 | KO3: 46320 | KP3: 46321 | KQ3: 46322 | KR3: 46323 | KS3: 46324 | KT3: 46325 | KU3: 46326 | KV3: 46327 | KW3: 46328 | KX3: 46329 | KY3: 46330 | KZ3: 46331 | LA3: 46332 | LB3: 46333 | LC3: 46334 | LD3: 46335 | LE3: 46336 | LF3: 46337 | LG3: 46338 | LH3: 46339 | LI3: 46340 | LJ3: 46341 | LK3: 46342 | LL3: 46343 | LM3: 46344 | LN3: 46345 | LO3: 46346 | LP3: 46347 | LQ3: 46348 | LR3: 46349 | LS3: 46350 | LT3: 46351 | LU3: 46352 | LV3: 46353 | LW3: 46354 | LX3: 46355 | LY3: 46356 | LZ3: 46357 | MA3: 46358 | MB3: 46359 | MC3: 46360 | MD3: 46361 | ME3: 46362 | MF3: 46363 | MG3: 46364 | MH3: 46365 | MI3: 46366 | MJ3: 46367 | MK3: 46368 | ML3: 46369 | MM3: 46370 | MN3: 46371 | MO3: 46372 | MP3: 46373 | MQ3: 46374 | MR3: 46375 | MS3: 46376 | MT3: 46377 | MU3: 46378 | MV3: 46379 | MW3: 46380 | MX3: 46381 | MY3: 46382 | MZ3: 46383 | NA3: 46384 | NB3: 46385 | NC3: 46386 | ND3: 46387 | NE3: Batas
D4: =TEXT(D3,"DDD") -> Thu | E4: =TEXT(E3,"DDD") -> Fri | F4: =TEXT(F3,"DDD") -> Sat | G4: =TEXT(G3,"DDD") -> Sun | H4: =TEXT(H3,"DDD") -> Mon | I4: =TEXT(I3,"DDD") -> Tue | J4: =TEXT(J3,"DDD") -> Wed | K4: =TEXT(K3,"DDD") -> Thu | ... ND4: =TEXT(ND3,"DDD") -> Thu | NE4: Batas
A5: 1 | B5: Gudang A | C5: Suci Rahmawati | I5: T | AA5: T | AC5: C | AM5: T | AN5: T | AT5: C | BQ5: C | CJ5: C | CK5: C | CL5: CS | GB5: C | GK5: T | GO5: C | IA5: C | IV5: C | NE5: Batas
A6: 2 | B6: Gudang A | C6: Nur Octaviani | O6: T | AQ6: T | BE6: T | CJ6: C | CK6: C | CL6: CS | GF6: CS | GH6: C | GJ6: C | IQ6: CS | NE6: Batas
A7: 3 | B7: Gudang A | C7: M. Farhan | E7: C | CJ7: C | CK7: C | CL7: C | EZ7: C | HY7: C | HZ7: C | IA7: C | NE7: Batas
A8: 4 | B8: Gudang A | C8: Nadia | J8: T | O8: T | X8: T | Z8: T | AJ8: T | AU8: T | AZ8: T | BA8: C | BE8: T | BI8: T | BM8: T | BN8: T | BP8: T | BW8: S | BZ8: C | CA8: C | CB8: C | CJ8: C | CK8: C | CL8: CS | DZ8: C | EF8: T | GX8: C | HD8: T | HO8: C | HP8: C | NE8: Batas
A9: 5 | B9: Gudang A | C9: Aan Turipno | O9: T | AA9: CS | CJ9: C | CK9: C | CL9: C | EZ9: C | GB9: C | GD9: T | HR9: T | JA9: C | JB9: C | JC9: C | NE9: Batas
A10: 6 | B10: Gudang A | C10: dika | E10: C | F10: C | O10: T | P10: T | AE10: T | AF10: T | CB10: C | CJ10: C | CK10: C | CL10: C | DF10: C | DG10: C | DI10: S | EZ10: C | HC10: C | HD10: T | NE10: Batas
A11: 7 | B11: Gudang A | C11: Mella Hariyati | J11: T | O11: T | P11: T | R11: T | V11: T | W11: T | X11: T | AD11: T | AF11: T | AJ11: T | AQ11: T | BE11: T | BM11: T | CJ11: C | CK11: C | CL11: CS | DB11: T | DP11: T | DQ11: T | DU11: CS | DX11: T | ER11: T | FD11: T | GY11: C | HQ11: T | NE11: Batas
A12: 8 | B12: Gudang A | C12: Egi Permana | M12: T | Z12: T | AD12: T | AQ12: C | BE12: T | BM12: T | CJ12: C | CK12: C | CL12: C | CS12: C | DJ12: T | DM12: T | DP12: T | DS12: T | DZ12: T | EI12: C | EO12: C | FO12: C | GE12: T | GJ12: C | GK12: T | GW12: T | GX12: C | HD12: C | HK12: T | HL12: T | IA12: T | IP12: C | IQ12: C | IS12: C | NE12: Batas
A13: 9 | B13: Gudang A | C13: Dede Irawan | E13: C | F13: C | M13: T | P13: T | T13: T | V13: T | AJ13: C | AK13: T | AO13: T | AR13: T | AS13: C | BA13: T | BL13: T | BS13: T | CA13: T | CJ13: C | CK13: C | CL13: C | CP13: T | EL13: T | EU13: C | FJ13: T | FX13: T | GS13: T | GV13: T | IB13: T | JG13: C | NE13: Batas
A14: 10 | B14: Gudang A | C14: eri mutaqin | M14: T | O14: T | P14: T | T14: T | CJ14: C | CK14: C | CL14: C | EU14: C | HJ14: C | IZ14: C | JA14: C | NE14: Batas
A15: 11 | B15: Gudang A | C15: Fiqri Amirulloh Maulidan | CJ15: C | CK15: C | CL15: C | NE15: Batas
A16: 12 | B16: Gudang A | C16: Jihan | CJ16: C | CK16: C | CL16: CS | NE16: Batas
A17: 13 | B17: Gudang A | C17: Samawi | F17: T | K17: T | M17: T | P17: T | T17: C | V17: C | AD17: T | AE17: T | AH17: T | AJ17: T | AK17: T | AM17: T | AN17: T | AO17: T | AQ17: T | AR17: T | AS17: T | AV17: T | AX17: T | BA17: T | BB17: T | BG17: C | BH17: T | BM17: T | BZ17: T | CJ17: C | CK17: C | CL17: C | DU17: T | DX17: T | EF17: T | EL17: T | EZ17: T | FA17: T | FK17: C | FP17: T | FX17: T | FY17: T | GD17: T | GE17: T | GF17: T | GO17: T | GP17: T | HN17: C | NE17: Batas
A18: 14 | B18: Gudang A | C18: Guruh Fathur Rohman | CJ18: C | CK18: C | CL18: C | NE18: Batas
A19: 15 | B19: Gudang A | C19: Rizal Tajali Akbar | E19: C | T19: C | V19: C | W19: C | BM19: T | CJ19: C | CK19: C | CL19: C | CN19: C | DB19: C | EA19: C | FB19: C | FM19: C | FO19: C | NE19: Batas
A20: 16 | B20: Gudang A | C20: Amrullah | CJ20: C | CK20: C | CL20: C | NE20: Batas
A21: 17 | B21: Gudang A | C21: Dede Komarudin | O21: T | Q21: C | V21: T | AJ21: C | BI21: T | BM21: T | BN21: C | CJ21: C | CK21: C | CL21: C | DS21: T | FX21: CS | GB21: C | HJ21: C | NE21: Batas
A22: 18 | B22: Gudang A | C22: Isti Rofah | Z22: T | BO22: T | CJ22: C | CK22: C | CL22: CS | EW22: CS | EZ22: C | GT22: CS | GV22: C | GW22: C | GZ22: C | NE22: Batas
A23: 19 | B23: Gudang A | C23: Muhammad Ihsan Iswahyudi | AJ23: C | AR23: T | BO23: T | BT23: T | BU23: C | CA23: C | CB23: T | CJ23: C | CK23: C | CL23: CS | CP23: C | DU23: CS | ES23: T | EV23: T | EW23: C | FB23: T | FC23: T | FD23: T | FF23: C | FJ23: T | FQ23: T | FT23: C | GE23: C | HH23: T | HQ23: T | HR23: T | NE23: Batas
A24: 20 | B24: Gudang A | C24: Iwan Setiawan | O24: T | P24: T | AE24: C | AJ24: T | BM24: C | BS24: CS | BU24: C | CJ24: C | CK24: C | CL24: C | DJ24: C | DQ24: T | EE24: C | FD24: C | HO24: CS | HZ24: S | IA24: S | NE24: Batas
A25: 21 | B25: Gudang A | C25: Noval Azhar | H25: T | I25: T | K25: T | M25: T | R25: T | T25: T | Z25: T | AF25: T | AH25: T | AN25: T | AR25: T | BM25: T | CA25: T | CB25: T | CJ25: C | CK25: C | CL25: C | CW25: T | CY25: T | DF25: T | DJ25: T | DK25: T | DM25: T | DR25: T | DS25: T | EE25: T | FF25: T | FI25: T | FO25: T | FT25: T | FU25: T | FW25: T | FY25: T | GD25: C | HG25: T | HS25: T | HV25: T | IE25: T | NE25: Batas
A26: 22 | B26: Gudang A | C26: Putri Maulida | E26: T | O26: T | R26: T | Y26: T | AJ26: T | AQ26: T | BE26: T | BV26: C | CJ26: C | CK26: C | CL26: C | EW26: CS | FI26: T | GK26: CS | GL26: S | HN26: C | HO26: CS | IP26: C | IQ26: CS | NE26: Batas
A27: 23 | B27: Gudang A | C27: Ali Imron | M27: T | O27: T | AA27: C | AE27: C | AJ27: T | AO27: T | BM27: T | BO27: C | BP27: C | CJ27: C | CK27: C | CL27: C | CN27: T | CW27: T | DB27: C | DF27: T | DK27: T | FR27: T | FX27: T | FY27: T | GE27: C | GF27: C | GM27: T | HJ27: T | HL27: T | HO27: T | HQ27: C | HZ27: T | IA27: T | IB27: T | NE27: Batas
A28: 24 | B28: Gudang A | C28: Riyan Setiawan | BC28: C | CJ28: C | CK28: C | CL28: C | DP28: C | GB28: C | GQ28: C | GS28: C | HJ28: C | HK28: C | HL28: C | NE28: Batas
A29: 25 | B29: Gudang A | C29: Kusnadi | F29: T | CJ29: C | CK29: C | CL29: C | DM29: T | FX29: C | FY29: S | NE29: Batas
A30: 26 | B30: Gudang A | C30: Hamdani | CJ30: C | CK30: C | CL30: CS | NE30: Batas
A31: 27 | B31: Gudang A | C31: Risa Srinita | K31: T | W31: T | Y31: T | AD31: T | AJ31: T | AU31: T | BE31: T | BF31: T | BN31: T | BZ31: T | CA31: C | CB31: C | CJ31: C | CK31: C | CL31: CS | CO31: T | DC31: T | DL31: T | DQ31: T | DS31: T | ED31: T | EE31: T | EF31: T | EH31: T | FG31: T | FT31: T | FU31: T | GH31: S | GX31: T | HA31: T | HC31: T | HF31: T | HJ31: T | HK31: T | HM31: T | HN31: T | HQ31: T | HU31: T | HY31: T | IV31: C | NE31: Batas
A32: 28 | B32: Gudang A | C32: Muhamad Imron Sopary | L32: T | Q32: T | R32: T | W32: T | Y32: T | Z32: T | AG32: T | AM32: T | AN32: T | AQ32: T | AR32: T | AS32: T | AU32: T | AV32: T | AX32: T | BE32: T | BG32: T | BI32: T | BM32: T | BQ32: T | BS32: T | CJ32: C | CK32: C | CL32: CS | CO32: T | CP32: T | CS32: C | CW32: C | DN32: T | DP32: C | DQ32: T | DX32: T | DZ32: T | ED32: T | EE32: T | EH32: T | ES32: T | FB32: T | FC32: T | FH32: T | FJ32: T | FK32: T | FP32: T | FQ32: T | FR32: T | FU32: T | FW32: T | FX32: T | GA32: T | GB32: T | GD32: T | GF32: T | GK32: C | HM32: T | HN32: T | HQ32: T | HY32: C | IB32: T | IC32: T | IE32: T | NE32: Batas
A33: 29 | B33: Gudang A | C33: Muhammad Fathir Alfarizi | AE33: C | CJ33: C | CK33: C | CL33: C | EU33: C | EV33: C | EW33: C | FF33: T | FY33: T | GC33: T | GE33: C | GF33: C | HS33: C | JO33: C | NE33: Batas
A34: 30 | B34: Gudang A | C34: Fikri Paturohman | BM34: T | CB34: C | CJ34: C | CK34: C | CL34: C | EZ34: C | FA34: C | FB34: C | GB34: C | GP34: C | GQ34: C | GR34: C | HG34: C | IA34: C | IT34: C | JC34: C | NE34: Batas
A35: 31 | B35: Gudang A | C35: Saiful Fisri | AE35: T | AF35: T | BP35: C | CJ35: C | CK35: C | CL35: C | CV35: T | CW35: C | DU35: C | EH35: C | FD35: C | FQ35: C | GE35: T | GF35: C | GU35: C | GV35: C | GW35: S | HH35: C | IC35: C | IX35: C
A36: 32 | B36: Gudang A | C36: M. Fariz Maulana | AK36: T | AQ36: T | BB36: T | BE36: T | CJ36: C | CK36: C | CL36: C
A37: 33 | B37: Gudang A | C37: Malik Irsad Abdullah | BO37: T | BP37: T | CJ37: C | CK37: C | CL37: C | CX37: T | CY37: T | DD37: T | DF37: T | DJ37: T | DR37: T | DS37: T | DU37: T | EA37: T | FF37: T | FI37: C | FO37: T | FQ37: T | GM37: T | GO37: T | GS37: C | HC37: C | HJ37: T | HU37: C | IB37: C | IC37: C | IJ37: C | JA37: C
A38: 34 | B38: Gudang A | C38: Fatul Muhni Khozali | CJ38: C | CK38: C | CL38: C | CX38: T | DC38: T | DK38: T | EU38: C | FA38: C | FB38: C | FC38: C | FJ38: T | FM38: C | HF38: T | HH38: C | HJ38: T | IB38: T | IU38: C
A39: 35 | B39: Gudang A | C39: Putrinesia Ramadhani H | AQ39: S | AR39: S | CJ39: C | CK39: C | CL39: C | EY39: S | IC39: T | ID39: T | NE39: Batas
A40: 36 | B40: Gudang A | C40: Intan Melani | CJ40: C | CK40: C | CL40: C | EB40: C | NE40: Batas
...

Sheet Rekap
A1: REKAP KEHADIRAN
M2: =VLOOKUP(C3,Setting!D2:E13,2,0) -> 09
B3: Pilih Bulan | C3: September | F3: *pilih bulan
A5: No. | B5: Lokasi | C5: Nama Karyawan | E5: Hadir | F5: Cuti | G5: Cuti Setengah Hari | H5: Sakit | I5: Terlambat | J5: Keluar Pagi | M5: Sisa Cuti
E6: H | F6: C | G6: CS | H6: S | I6: T | J6: KP
A7: 1 | B7: =Absensi!B5 -> Gudang A | C7: =Absensi!C5 -> Suci Rahmawati | D7: =B7&C7 -> Gudang ASuci Rahmawati | E7: =COUNTIFS(Absensi!$D5:$ND5,Rekap!E$6,Absensi!$D$2:$ND$2,$M$2) -> 0 | F7: =COUNTIFS(Absensi!$D5:$ND5,Rekap!F$6,Absensi!$D$2:$ND$2,$M$2) -> 1 | G7: =COUNTIFS(Absensi!$D5:$ND5,Rekap!G$6,Absensi!$D$2:$ND$2,$M$2) -> 0 | H7: =COUNTIFS(Absensi!$D5:$ND5,Rekap!H$6,Absensi!$D$2:$ND$2,$M$2) -> 0 | I7: =COUNTIFS(Absensi!$D5:$ND5,Rekap!I$6,Absensi!$D$2:$ND$2,$M$2) -> 0 | J7: =COUNTIFS(Absensi!$D5:$ND5,Rekap!J$6,Absensi!$D$2:$ND$2,$M$2) -> 0 | M7: =IF($M$2="01",SUMIF(Test!$D:$D,Rekap!D7,Test!$AC:$AC),IF($M$2="02",SUMIF(Test!$D:$D,Rekap!D7,Test!$AD:$AD),IF($M$2="03",SUMIF(Test!$D:$D,Rekap!D7,Test!$AE:$AE),IF($M$2="04",SUMIF(Test!$D:$D,Rekap!D7,Test!$AF:$AF),IF($M$2="05",SUMIF(Test!$D:$D,Rekap!D7,Test!$AG:$AG),IF($M$2="06",SUMIF(Test!$D:$D,Rekap!D7,Test!$AH:$AH),IF($M$2="07",SUMIF(Test!$D:$D,Rekap!D7,Test!$AI:$AI),IF($M$2="08",SUMIF(Test!$D:$D,Rekap!D7,Test!$AJ:$AJ),IF($M$2="09",SUMIF(Test!$D:$D,Rekap!D7,Test!$AK:$AK),IF($M$2="10",SUMIF(Test!$D:$D,Rekap!D7,Test!$AL:$AL),IF($M$2="11",SUMIF(Test!$D:$D,Rekap!D7,Test!$AM:$AM),IF($M$2="12",SUMIF(Test!$D:$D,Rekap!D7,Test!$AN:$AN),0)))))))))))) -> 2.5
A8: 2 | B8: =Absensi!B6 -> Gudang A | C8: =Absensi!C6 -> Nur Octaviani | D8: =B8&C8 -> Gudang ANur Octaviani | E8: =COUNTIFS(Absensi!$D6:$ND6,Rekap!E$6,Absensi!$D$2:$ND$2,$M$2) -> 0 | F8: =COUNTIFS(Absensi!$D6:$ND6,Rekap!F$6,Absensi!$D$2:$ND$2,$M$2) -> 0 | G8: =COUNTIFS(Absensi!$D6:$ND6,Rekap!G$6,Absensi!$D$2:$ND$2,$M$2) -> 1 | H8: =COUNTIFS(Absensi!$D6:$ND6,Rekap!H$6,Absensi!$D$2:$ND$2,$M$2) -> 0 | I8: =COUNTIFS(Absensi!$D6:$ND6,Rekap!I$6,Absensi!$D$2:$ND$2,$M$2) -> 0 | J8: =COUNTIFS(Absensi!$D6:$ND6,Rekap!J$6,Absensi!$D$2:$ND$2,$M$2) -> 0 | M8: =IF($M$2="01",SUMIF(Test!$D:$D,Rekap!D8,Test!$AC:$AC),IF($M$2="02",SUMIF(Test!$D:$D,Rekap!D8,Test!$AD:$AD),IF($M$2="03",SUMIF(Test!$D:$D,Rekap!D8,Test!$AE:$AE),IF($M$2="04",SUMIF(Test!$D:$D,Rekap!D8,Test!$AF:$AF),IF($M$2="05",SUMIF(Test!$D:$D,Rekap!D8,Test!$AG:$AG),IF($M$2="06",SUMIF(Test!$D:$D,Rekap!D8,Test!$AH:$AH),IF($M$2="07",SUMIF(Test!$D:$D,Rekap!D8,Test!$AI:$AI),IF($M$2="08",SUMIF(Test!$D:$D,Rekap!D8,Test!$AJ:$AJ),IF($M$2="09",SUMIF(Test!$D:$D,Rekap!D8,Test!$AK:$AK),IF($M$2="10",SUMIF(Test!$D:$D,Rekap!D8,Test!$AL:$AL),IF($M$2="11",SUMIF(Test!$D:$D,Rekap!D8,Test!$AM:$AM),IF($M$2="12",SUMIF(Test!$D:$D,Rekap!D8,Test!$AN:$AN),0)))))))))))) -> 6.5
A9: 3 | B9: =Absensi!B7 -> Gudang A | C9: =Absensi!C7 -> M. Farhan | D9: =B9&C9 -> Gudang AM. Farhan | E9: =COUNTIFS(Absensi!$D7:$ND7,Rekap!E$6,Absensi!$D$2:$ND$2,$M$2) -> 0 | F9: =COUNTIFS(Absensi!$D7:$ND7,Rekap!F$6,Absensi!$D$2:$ND$2,$M$2) -> 0 | G9: =COUNTIFS(Absensi!$D7:$ND7,Rekap!G$6,Absensi!$D$2:$ND$2,$M$2) -> 0 | H9: =COUNTIFS(Absensi!$D7:$ND7,Rekap!H$6,Absensi!$D$2:$ND$2,$M$2) -> 0 | I9: =COUNTIFS(Absensi!$D7:$ND7,Rekap!I$6,Absensi!$D$2:$ND$2,$M$2) -> 0 | J9: =COUNTIFS(Absensi!$D7:$ND7,Rekap!J$6,Absensi!$D$2:$ND$2,$M$2) -> 0 | M9: =IF($M$2="01",SUMIF(Test!$D:$D,Rekap!D9,Test!$AC:$AC),IF($M$2="02",SUMIF(Test!$D:$D,Rekap!D9,Test!$AD:$AD),IF($M$2="03",SUMIF(Test!$D:$D,Rekap!D9,Test!$AE:$AE),IF($M$2="04",SUMIF(Test!$D:$D,Rekap!D9,Test!$AF:$AF),IF($M$2="05",SUMIF(Test!$D:$D,Rekap!D9,Test!$AG:$AG),IF($M$2="06",SUMIF(Test!$D:$D,Rekap!D9,Test!$AH:$AH),IF($M$2="07",SUMIF(Test!$D:$D,Rekap!D9,Test!$AI:$AI),IF($M$2="08",SUMIF(Test!$D:$D,Rekap!D9,Test!$AJ:$AJ),IF($M$2="09",SUMIF(Test!$D:$D,Rekap!D9,Test!$AK:$AK),IF($M$2="10",SUMIF(Test!$D:$D,Rekap!D9,Test!$AL:$AL),IF($M$2="11",SUMIF(Test!$D:$D,Rekap!D9,Test!$AM:$AM),IF($M$2="12",SUMIF(Test!$D:$D,Rekap!D9,Test!$AN:$AN),0)))))))))))) -> 4
A10: 4 | B10: =Absensi!B8 -> Gudang A | C10: =Absensi!C8 -> Nadia | D10: =B10&C10 -> Gudang ANadia | E10: =COUNTIFS(Absensi!$D8:$ND8,Rekap!E$6,Absensi!$D$2:$ND$2,$M$2) -> 0 | F10: =COUNTIFS(Absensi!$D8:$ND8,Rekap!F$6,Absensi!$D$2:$ND$2,$M$2) -> 0 | G10: =COUNTIFS(Absensi!$D8:$ND8,Rekap!G$6,Absensi!$D$2:$ND$2,$M$2) -> 0 | H10: =COUNTIFS(Absensi!$D8:$ND8,Rekap!H$6,Absensi!$D$2:$ND$2,$M$2) -> 0 | I10: =COUNTIFS(Absensi!$D8:$ND8,Rekap!I$6,Absensi!$D$2:$ND$2,$M$2) -> 0 | J10: =COUNTIFS(Absensi!$D8:$ND8,Rekap!J$6,Absensi!$D$2:$ND$2,$M$2) -> 0 | M10: =IF($M$2="01",SUMIF(Test!$D:$D,Rekap!D10,Test!$AC:$AC),IF($M$2="02",SUMIF(Test!$D:$D,Rekap!D10,Test!$AD:$AD),IF($M$2="03",SUMIF(Test!$D:$D,Rekap!D10,Test!$AE:$AE),IF($M$2="04",SUMIF(Test!$D:$D,Rekap!D10,Test!$AF:$AF),IF($M$2="05",SUMIF(Test!$D:$D,Rekap!D10,Test!$AG:$AG),IF($M$2="06",SUMIF(Test!$D:$D,Rekap!D10,Test!$AH:$AH),IF($M$2="07",SUMIF(Test!$D:$D,Rekap!D10,Test!$AI:$AI),IF($M$2="08",SUMIF(Test!$D:$D,Rekap!D10,Test!$AJ:$AJ),IF($M$2="09",SUMIF(Test!$D:$D,Rekap!D10,Test!$AK:$AK),IF($M$2="10",SUMIF(Test!$D:$D,Rekap!D10,Test!$AL:$AL),IF($M$2="11",SUMIF(Test!$D:$D,Rekap!D10,Test!$AM:$AM),IF($M$2="12",SUMIF(Test!$D:$D,Rekap!D10,Test!$AN:$AN),0)))))))))))) -> 1.5
A11: 5 | B11: =Absensi!B9 -> Gudang A | C11: =Absensi!C9 -> Aan Turipno | D11: =B11&C11 -> Gudang AAan Turipno | E11: =COUNTIFS(Absensi!$D9:$ND9,Rekap!E$6,Absensi!$D$2:$ND$2,$M$2) -> 0 | F11: =COUNTIFS(Absensi!$D9:$ND9,Rekap!F$6,Absensi!$D$2:$ND$2,$M$2) -> 3 | G11: =COUNTIFS(Absensi!$D9:$ND9,Rekap!G$6,Absensi!$D$2:$ND$2,$M$2) -> 0 | H11: =COUNTIFS(Absensi!$D9:$ND9,Rekap!H$6,Absensi!$D$2:$ND$2,$M$2) -> 0 | I11: =COUNTIFS(Absensi!$D9:$ND9,Rekap!I$6,Absensi!$D$2:$ND$2,$M$2) -> 0 | J11: =COUNTIFS(Absensi!$D9:$ND9,Rekap!J$6,Absensi!$D$2:$ND$2,$M$2) -> 0 | M11: =IF($M$2="01",SUMIF(Test!$D:$D,Rekap!D11,Test!$AC:$AC),IF($M$2="02",SUMIF(Test!$D:$D,Rekap!D11,Test!$AD:$AD),IF($M$2="03",SUMIF(Test!$D:$D,Rekap!D11,Test!$AE:$AE),IF($M$2="04",SUMIF(Test!$D:$D,Rekap!D11,Test!$AF:$AF),IF($M$2="05",SUMIF(Test!$D:$D,Rekap!D11,Test!$AG:$AG),IF($M$2="06",SUMIF(Test!$D:$D,Rekap!D11,Test!$AH:$AH),IF($M$2="07",SUMIF(Test!$D:$D,Rekap!D11,Test!$AI:$AI),IF($M$2="08",SUMIF(Test!$D:$D,Rekap!D11,Test!$AJ:$AJ),IF($M$2="09",SUMIF(Test!$D:$D,Rekap!D11,Test!$AK:$AK),IF($M$2="10",SUMIF(Test!$D:$D,Rekap!D11,Test!$AL:$AL),IF($M$2="11",SUMIF(Test!$D:$D,Rekap!D11,Test!$AM:$AM),IF($M$2="12",SUMIF(Test!$D:$D,Rekap!D11,Test!$AN:$AN),0)))))))))))) -> 3.5
A12: 6 | B12: =Absensi!B10 -> Gudang A | C12: =Absensi!C10 -> dika | D12: =B12&C12 -> Gudang Adika | E12: =COUNTIFS(Absensi!$D10:$ND10,Rekap!E$6,Absensi!$D$2:$ND$2,$M$2) -> 0 | F12: =COUNTIFS(Absensi!$D10:$ND10,Rekap!F$6,Absensi!$D$2:$ND$2,$M$2) -> 0 | G12: =COUNTIFS(Absensi!$D10:$ND10,Rekap!G$6,Absensi!$D$2:$ND$2,$M$2) -> 0 | H12: =COUNTIFS(Absensi!$D10:$ND10,Rekap!H$6,Absensi!$D$2:$ND$2,$M$2) -> 0 | I12: =COUNTIFS(Absensi!$D10:$ND10,Rekap!I$6,Absensi!$D$2:$ND$2,$M$2) -> 0 | J12: =COUNTIFS(Absensi!$D10:$ND10,Rekap!J$6,Absensi!$D$2:$ND$2,$M$2) -> 0 | M12: =IF($M$2="01",SUMIF(Test!$D:$D,Rekap!D12,Test!$AC:$AC),IF($M$2="02",SUMIF(Test!$D:$D,Rekap!D12,Test!$AD:$AD),IF($M$2="03",SUMIF(Test!$D:$D,Rekap!D12,Test!$AE:$AE),IF($M$2="04",SUMIF(Test!$D:$D,Rekap!D12,Test!$AF:$AF),IF($M$2="05",SUMIF(Test!$D:$D,Rekap!D12,Test!$AG:$AG),IF($M$2="06",SUMIF(Test!$D:$D,Rekap!D12,Test!$AH:$AH),IF($M$2="07",SUMIF(Test!$D:$D,Rekap!D12,Test!$AI:$AI),IF($M$2="08",SUMIF(Test!$D:$D,Rekap!D12,Test!$AJ:$AJ),IF($M$2="09",SUMIF(Test!$D:$D,Rekap!D12,Test!$AK:$AK),IF($M$2="10",SUMIF(Test!$D:$D,Rekap!D12,Test!$AL:$AL),IF($M$2="11",SUMIF(Test!$D:$D,Rekap!D12,Test!$AM:$AM),IF($M$2="12",SUMIF(Test!$D:$D,Rekap!D12,Test!$AN:$AN),0)))))))))))) -> 2
A13: 7 | B13: =Absensi!B11 -> Gudang A | C13: =Absensi!C11 -> Mella Hariyati | D13: =B13&C13 -> Gudang AMella Hariyati | E13: =COUNTIFS(Absensi!$D11:$ND11,Rekap!E$6,Absensi!$D$2:$ND$2,$M$2) -> 0 | F13: =COUNTIFS(Absensi!$D11:$ND11,Rekap!F$6,Absensi!$D$2:$ND$2,$M$2) -> 0 | G13: =COUNTIFS(Absensi!$D11:$ND11,Rekap!G$6,Absensi!$D$2:$ND$2,$M$2) -> 0 | H13: =COUNTIFS(Absensi!$D11:$ND11,Rekap!H$6,Absensi!$D$2:$ND$2,$M$2) -> 0 | I13: =COUNTIFS(Absensi!$D11:$ND11,Rekap!I$6,Absensi!$D$2:$ND$2,$M$2) -> 0 | J13: =COUNTIFS(Absensi!$D11:$ND11,Rekap!J$6,Absensi!$D$2:$ND$2,$M$2) -> 0 | M13: =IF($M$2="01",SUMIF(Test!$D:$D,Rekap!D13,Test!$AC:$AC),IF($M$2="02",SUMIF(Test!$D:$D,Rekap!D13,Test!$AD:$AD),IF($M$2="03",SUMIF(Test!$D:$D,Rekap!D13,Test!$AE:$AE),IF($M$2="04",SUMIF(Test!$D:$D,Rekap!D13,Test!$AF:$AF),IF($M$2="05",SUMIF(Test!$D:$D,Rekap!D13,Test!$AG:$AG),IF($M$2="06",SUMIF(Test!$D:$D,Rekap!D13,Test!$AH:$AH),IF($M$2="07",SUMIF(Test!$D:$D,Rekap!D13,Test!$AI:$AI),IF($M$2="08",SUMIF(Test!$D:$D,Rekap!D13,Test!$AJ:$AJ),IF($M$2="09",SUMIF(Test!$D:$D,Rekap!D13,Test!$AK:$AK),IF($M$2="10",SUMIF(Test!$D:$D,Rekap!D13,Test!$AL:$AL),IF($M$2="11",SUMIF(Test!$D:$D,Rekap!D13,Test!$AM:$AM),IF($M$2="12",SUMIF(Test!$D:$D,Rekap!D13,Test!$AN:$AN),0)))))))))))) -> 8
A14: 8 | B14: =Absensi!B12 -> Gudang A | C14: =Absensi!C12 -> Egi Permana | D14: =B14&C14 -> Gudang AEgi Permana | E14: =COUNTIFS(Absensi!$D12:$ND12,Rekap!E$6,Absensi!$D$2:$ND$2,$M$2) -> 0 | F14: =COUNTIFS(Absensi!$D12:$ND12,Rekap!F$6,Absensi!$D$2:$ND$2,$M$2) -> 3 | G14: =COUNTIFS(Absensi!$D12:$ND12,Rekap!G$6,Absensi!$D$2:$ND$2,$M$2) -> 0 | H14: =COUNTIFS(Absensi!$D12:$ND12,Rekap!H$6,Absensi!$D$2:$ND$2,$M$2) -> 0 | I14: =COUNTIFS(Absensi!$D12:$ND12,Rekap!I$6,Absensi!$D$2:$ND$2,$M$2) -> 0 | J14: =COUNTIFS(Absensi!$D12:$ND12,Rekap!J$6,Absensi!$D$2:$ND$2,$M$2) -> 0 | M14: =IF($M$2="01",SUMIF(Test!$D:$D,Rekap!D14,Test!$AC:$AC),IF($M$2="02",SUMIF(Test!$D:$D,Rekap!D14,Test!$AD:$AD),IF($M$2="03",SUMIF(Test!$D:$D,Rekap!D14,Test!$AE:$AE),IF($M$2="04",SUMIF(Test!$D:$D,Rekap!D14,Test!$AF:$AF),IF($M$2="05",SUMIF(Test!$D:$D,Rekap!D14,Test!$AG:$AG),IF($M$2="06",SUMIF(Test!$D:$D,Rekap!D14,Test!$AH:$AH),IF($M$2="07",SUMIF(Test!$D:$D,Rekap!D14,Test!$AI:$AI),IF($M$2="08",SUMIF(Test!$D:$D,Rekap!D14,Test!$AJ:$AJ),IF($M$2="09",SUMIF(Test!$D:$D,Rekap!D14,Test!$AK:$AK),IF($M$2="10",SUMIF(Test!$D:$D,Rekap!D14,Test!$AL:$AL),IF($M$2="11",SUMIF(Test!$D:$D,Rekap!D14,Test!$AM:$AM),IF($M$2="12",SUMIF(Test!$D:$D,Rekap!D14,Test!$AN:$AN),0)))))))))))) -> -2
A15: 9 | B15: =Absensi!B13 -> Gudang A | C15: =Absensi!C13 -> Dede Irawan | D15: =B15&C15 -> Gudang ADede Irawan | E15: =COUNTIFS(Absensi!$D13:$ND13,Rekap!E$6,Absensi!$D$2:$ND$2,$M$2) -> 0 | F15: =COUNTIFS(Absensi!$D13:$ND13,Rekap!F$6,Absensi!$D$2:$ND$2,$M$2) -> 1 | G15: =COUNTIFS(Absensi!$D13:$ND13,Rekap!G$6,Absensi!$D$2:$ND$2,$M$2) -> 0 | H15: =COUNTIFS(Absensi!$D13:$ND13,Rekap!H$6,Absensi!$D$2:$ND$2,$M$2) -> 0 | I15: =COUNTIFS(Absensi!$D13:$ND13,Rekap!I$6,Absensi!$D$2:$ND$2,$M$2) -> 0 | J15: =COUNTIFS(Absensi!$D13:$ND13,Rekap!J$6,Absensi!$D$2:$ND$2,$M$2) -> 0 | M15: =IF($M$2="01",SUMIF(Test!$D:$D,Rekap!D15,Test!$AC:$AC),IF($M$2="02",SUMIF(Test!$D:$D,Rekap!D15,Test!$AD:$AD),IF($M$2="03",SUMIF(Test!$D:$D,Rekap!D15,Test!$AE:$AE),IF($M$2="04",SUMIF(Test!$D:$D,Rekap!D15,Test!$AF:$AF),IF($M$2="05",SUMIF(Test!$D:$D,Rekap!D15,Test!$AG:$AG),IF($M$2="06",SUMIF(Test!$D:$D,Rekap!D15,Test!$AH:$AH),IF($M$2="07",SUMIF(Test!$D:$D,Rekap!D15,Test!$AI:$AI),IF($M$2="08",SUMIF(Test!$D:$D,Rekap!D15,Test!$AJ:$AJ),IF($M$2="09",SUMIF(Test!$D:$D,Rekap!D15,Test!$AK:$AK),IF($M$2="10",SUMIF(Test!$D:$D,Rekap!D15,Test!$AL:$AL),IF($M$2="11",SUMIF(Test!$D:$D,Rekap!D15,Test!$AM:$AM),IF($M$2="12",SUMIF(Test!$D:$D,Rekap!D15,Test!$AN:$AN),0)))))))))))) -> 3
A16: 10 | B16: =Absensi!B14 -> Gudang A | C16: =Absensi!C14 -> eri mutaqin | D16: =B16&C16 -> Gudang Aeri mutaqin | E16: =COUNTIFS(Absensi!$D14:$ND14,Rekap!E$6,Absensi!$D$2:$ND$2,$M$2) -> 0 | F16: =COUNTIFS(Absensi!$D14:$ND14,Rekap!F$6,Absensi!$D$2:$ND$2,$M$2) -> 2 | G16: =COUNTIFS(Absensi!$D14:$ND14,Rekap!G$6,Absensi!$D$2:$ND$2,$M$2) -> 0 | H16: =COUNTIFS(Absensi!$D14:$ND14,Rekap!H$6,Absensi!$D$2:$ND$2,$M$2) -> 0 | I16: =COUNTIFS(Absensi!$D14:$ND14,Rekap!I$6,Absensi!$D$2:$ND$2,$M$2) -> 0 | J16: =COUNTIFS(Absensi!$D14:$ND14,Rekap!J$6,Absensi!$D$2:$ND$2,$M$2) -> 0 | M16: =IF($M$2="01",SUMIF(Test!$D:$D,Rekap!D16,Test!$AC:$AC),IF($M$2="02",SUMIF(Test!$D:$D,Rekap!D16,Test!$AD:$AD),IF($M$2="03",SUMIF(Test!$D:$D,Rekap!D16,Test!$AE:$AE),IF($M$2="04",SUMIF(Test!$D:$D,Rekap!D16,Test!$AF:$AF),IF($M$2="05",SUMIF(Test!$D:$D,Rekap!D16,Test!$AG:$AG),IF($M$2="06",SUMIF(Test!$D:$D,Rekap!D16,Test!$AH:$AH),IF($M$2="07",SUMIF(Test!$D:$D,Rekap!D16,Test!$AI:$AI),IF($M$2="08",SUMIF(Test!$D:$D,Rekap!D16,Test!$AJ:$AJ),IF($M$2="09",SUMIF(Test!$D:$D,Rekap!D16,Test!$AK:$AK),IF($M$2="10",SUMIF(Test!$D:$D,Rekap!D16,Test!$AL:$AL),IF($M$2="11",SUMIF(Test!$D:$D,Rekap!D16,Test!$AM:$AM),IF($M$2="12",SUMIF(Test!$D:$D,Rekap!D16,Test!$AN:$AN),0)))))))))))) -> 5
A17: 11 | B17: =Absensi!B15 -> Gudang A | C17: =Absensi!C15 -> Fiqri Amirulloh Maulidan | D17: =B17&C17 -> Gudang AFiqri Amirulloh Maulidan | E17: =COUNTIFS(Absensi!$D15:$ND15,Rekap!E$6,Absensi!$D$2:$ND$2,$M$2) -> 0 | F17: =COUNTIFS(Absensi!$D15:$ND15,Rekap!F$6,Absensi!$D$2:$ND$2,$M$2) -> 0 | G17: =COUNTIFS(Absensi!$D15:$ND15,Rekap!G$6,Absensi!$D$2:$ND$2,$M$2) -> 0 | H17: =COUNTIFS(Absensi!$D15:$ND15,Rekap!H$6,Absensi!$D$2:$ND$2,$M$2) -> 0 | I17: =COUNTIFS(Absensi!$D15:$ND15,Rekap!I$6,Absensi!$D$2:$ND$2,$M$2) -> 0 | J17: =COUNTIFS(Absensi!$D15:$ND15,Rekap!J$6,Absensi!$D$2:$ND$2,$M$2) -> 0 | M17: =IF($M$2="01",SUMIF(Test!$D:$D,Rekap!D17,Test!$AC:$AC),IF($M$2="02",SUMIF(Test!$D:$D,Rekap!D17,Test!$AD:$AD),IF($M$2="03",SUMIF(Test!$D:$D,Rekap!D17,Test!$AE:$AE),IF($M$2="04",SUMIF(Test!$D:$D,Rekap!D17,Test!$AF:$AF),IF($M$2="05",SUMIF(Test!$D:$D,Rekap!D17,Test!$AG:$AG),IF($M$2="06",SUMIF(Test!$D:$D,Rekap!D17,Test!$AH:$AH),IF($M$2="07",SUMIF(Test!$D:$D,Rekap!D17,Test!$AI:$AI),IF($M$2="08",SUMIF(Test!$D:$D,Rekap!D17,Test!$AJ:$AJ),IF($M$2="09",SUMIF(Test!$D:$D,Rekap!D17,Test!$AK:$AK),IF($M$2="10",SUMIF(Test!$D:$D,Rekap!D17,Test!$AL:$AL),IF($M$2="11",SUMIF(Test!$D:$D,Rekap!D17,Test!$AM:$AM),IF($M$2="12",SUMIF(Test!$D:$D,Rekap!D17,Test!$AN:$AN),0)))))))))))) -> 9
A18: 12 | B18: =Absensi!B16 -> Gudang A | C18: =Absensi!C16 -> Jihan | D18: =B18&C18 -> Gudang AJihan | E18: =COUNTIFS(Absensi!$D16:$ND16,Rekap!E$6,Absensi!$D$2:$ND$2,$M$2) -> 0 | F18: =COUNTIFS(Absensi!$D16:$ND16,Rekap!F$6,Absensi!$D$2:$ND$2,$M$2) -> 0 | G18: =COUNTIFS(Absensi!$D16:$ND16,Rekap!G$6,Absensi!$D$2:$ND$2,$M$2) -> 0 | H18: =COUNTIFS(Absensi!$D16:$ND16,Rekap!H$6,Absensi!$D$2:$ND$2,$M$2) -> 0 | I18: =COUNTIFS(Absensi!$D16:$ND16,Rekap!I$6,Absensi!$D$2:$ND$2,$M$2) -> 0 | J18: =COUNTIFS(Absensi!$D16:$ND16,Rekap!J$6,Absensi!$D$2:$ND$2,$M$2) -> 0 | M18: =IF($M$2="01",SUMIF(Test!$D:$D,Rekap!D18,Test!$AC:$AC),IF($M$2="02",SUMIF(Test!$D:$D,Rekap!D18,Test!$AD:$AD),IF($M$2="03",SUMIF(Test!$D:$D,Rekap!D18,Test!$AE:$AE),IF($M$2="04",SUMIF(Test!$D:$D,Rekap!D18,Test!$AF:$AF),IF($M$2="05",SUMIF(Test!$D:$D,Rekap!D18,Test!$AG:$AG),IF($M$2="06",SUMIF(Test!$D:$D,Rekap!D18,Test!$AH:$AH),IF($M$2="07",SUMIF(Test!$D:$D,Rekap!D18,Test!$AI:$AI),IF($M$2="08",SUMIF(Test!$D:$D,Rekap!D18,Test!$AJ:$AJ),IF($M$2="09",SUMIF(Test!$D:$D,Rekap!D18,Test!$AK:$AK),IF($M$2="10",SUMIF(Test!$D:$D,Rekap!D18,Test!$AL:$AL),IF($M$2="11",SUMIF(Test!$D:$D,Rekap!D18,Test!$AM:$AM),IF($M$2="12",SUMIF(Test!$D:$D,Rekap!D18,Test!$AN:$AN),0)))))))))))) -> 9.5
... A107: 101 | B107: =Absensi!B105 -> Reef Plus | C107: =Absensi!C105 -> Indra | D107: =B107&C107 -> Reef PlusIndra | E107: =COUNTIFS(Absensi!$D105:$ND105,Rekap!E$6,Absensi!$D$2:$ND$2,$M$2) -> 0 | F107: =COUNTIFS(Absensi!$D105:$ND105,Rekap!F$6,Absensi!$D$2:$ND$2,$M$2) -> 1 | G107: =COUNTIFS(Absensi!$D105:$ND105,Rekap!G$6,Absensi!$D$2:$ND$2,$M$2) -> 0 | H107: =COUNTIFS(Absensi!$D105:$ND105,Rekap!H$6,Absensi!$D$2:$ND$2,$M$2) -> 0 | I107: =COUNTIFS(Absensi!$D105:$ND105,Rekap!I$6,Absensi!$D$2:$ND$2,$M$2) -> 0 | J107: =COUNTIFS(Absensi!$D105:$ND105,Rekap!J$6,Absensi!$D$2:$ND$2,$M$2) -> 0 | M107: =IF($M$2="01",SUMIF(Test!$D:$D,Rekap!D107,Test!$AC:$AC),IF($M$2="02",SUMIF(Test!$D:$D,Rekap!D107,Test!$AD:$AD),IF($M$2="03",SUMIF(Test!$D:$D,Rekap!D107,Test!$AE:$AE),IF($M$2="04",SUMIF(Test!$D:$D,Rekap!D107,Test!$AF:$AF),IF($M$2="05",SUMIF(Test!$D:$D,Rekap!D107,Test!$AG:$AG),IF($M$2="06",SUMIF(Test!$D:$D,Rekap!D107,Test!$AH:$AH),IF($M$2="07",SUMIF(Test!$D:$D,Rekap!D107,Test!$AI:$AI),IF($M$2="08",SUMIF(Test!$D:$D,Rekap!D107,Test!$AJ:$AJ),IF($M$2="09",SUMIF(Test!$D:$D,Rekap!D107,Test!$AK:$AK),IF($M$2="10",SUMIF(Test!$D:$D,Rekap!D107,Test!$AL:$AL),IF($M$2="11",SUMIF(Test!$D:$D,Rekap!D107,Test!$AM:$AM),IF($M$2="12",SUMIF(Test!$D:$D,Rekap!D107,Test!$AN:$AN),0)))))))))))) -> -6
A108: 102 | B108: =Absensi!B106 -> Reef Plus | C108: Agus | D108: =B108&C108 -> Reef PlusAgus | E108: =COUNTIFS(Absensi!$D106:$ND106,Rekap!E$6,Absensi!$D$2:$ND$2,$M$2) -> 0 | F108: =COUNTIFS(Absensi!$D106:$ND106,Rekap!F$6,Absensi!$D$2:$ND$2,$M$2) -> 0 | G108: =COUNTIFS(Absensi!$D106:$ND106,Rekap!G$6,Absensi!$D$2:$ND$2,$M$2) -> 0 | H108: =COUNTIFS(Absensi!$D106:$ND106,Rekap!H$6,Absensi!$D$2:$ND$2,$M$2) -> 0 | I108: =COUNTIFS(Absensi!$D106:$ND106,Rekap!I$6,Absensi!$D$2:$ND$2,$M$2) -> 0 | J108: =COUNTIFS(Absensi!$D106:$ND106,Rekap!J$6,Absensi!$D$2:$ND$2,$M$2) -> 0 | M108: =IF($M$2="01",SUMIF(Test!$D:$D,Rekap!D108,Test!$AC:$AC),IF($M$2="02",SUMIF(Test!$D:$D,Rekap!D108,Test!$AD:$AD),IF($M$2="03",SUMIF(Test!$D:$D,Rekap!D108,Test!$AE:$AE),IF($M$2="04",SUMIF(Test!$D:$D,Rekap!D108,Test!$AF:$AF),IF($M$2="05",SUMIF(Test!$D:$D,Rekap!D108,Test!$AG:$AG),IF($M$2="06",SUMIF(Test!$D:$D,Rekap!D108,Test!$AH:$AH),IF($M$2="07",SUMIF(Test!$D:$D,Rekap!D108,Test!$AI:$AI),IF($M$2="08",SUMIF(Test!$D:$D,Rekap!D108,Test!$AJ:$AJ),IF($M$2="09",SUMIF(Test!$D:$D,Rekap!D108,Test!$AK:$AK),IF($M$2="10",SUMIF(Test!$D:$D,Rekap!D108,Test!$AL:$AL),IF($M$2="11",SUMIF(Test!$D:$D,Rekap!D108,Test!$AM:$AM),IF($M$2="12",SUMIF(Test!$D:$D,Rekap!D108,Test!$AN:$AN),0)))))))))))) -> 0
A109: 103 | B109: =Absensi!B107 -> Kebayoran Lama | C109: =Absensi!C107 -> Edi Kuswanto | D109: =B109&C109 -> Kebayoran LamaEdi Kuswanto | E109: =COUNTIFS(Absensi!$D107:$ND107,Rekap!E$6,Absensi!$D$2:$ND$2,$M$2) -> 0 | F109: =COUNTIFS(Absensi!$D107:$ND107,Rekap!F$6,Absensi!$D$2:$ND$2,$M$2) -> 0 | G109: =COUNTIFS(Absensi!$D107:$ND107,Rekap!G$6,Absensi!$D$2:$ND$2,$M$2) -> 0 | H109: =COUNTIFS(Absensi!$D107:$ND107,Rekap!H$6,Absensi!$D$2:$ND$2,$M$2) -> 0 | I109: =COUNTIFS(Absensi!$D107:$ND107,Rekap!I$6,Absensi!$D$2:$ND$2,$M$2) -> 0 | J109: =COUNTIFS(Absensi!$D107:$ND107,Rekap!J$6,Absensi!$D$2:$ND$2,$M$2) -> 0 | M109: =IF($M$2="01",SUMIF(Test!$D:$D,Rekap!D109,Test!$AC:$AC),IF($M$2="02",SUMIF(Test!$D:$D,Rekap!D109,Test!$AD:$AD),IF($M$2="03",SUMIF(Test!$D:$D,Rekap!D109,Test!$AE:$AE),IF($M$2="04",SUMIF(Test!$D:$D,Rekap!D109,Test!$AF:$AF),IF($M$2="05",SUMIF(Test!$D:$D,Rekap!D109,Test!$AG:$AG),IF($M$2="06",SUMIF(Test!$D:$D,Rekap!D109,Test!$AH:$AH),IF($M$2="07",SUMIF(Test!$D:$D,Rekap!D109,Test!$AI:$AI),IF($M$2="08",SUMIF(Test!$D:$D,Rekap!D109,Test!$AJ:$AJ),IF($M$2="09",SUMIF(Test!$D:$D,Rekap!D109,Test!$AK:$AK),IF($M$2="10",SUMIF(Test!$D:$D,Rekap!D109,Test!$AL:$AL),IF($M$2="11",SUMIF(Test!$D:$D,Rekap!D109,Test!$AM:$AM),IF($M$2="12",SUMIF(Test!$D:$D,Rekap!D109,Test!$AN:$AN),0)))))))))))) -> 12
A110: 104 | B110: =Absensi!B108 -> Kebayoran Lama | C110: =Absensi!C108 -> Iwan hendrawan | D110: =B110&C110 -> Kebayoran LamaIwan hendrawan | E110: =COUNTIFS(Absensi!$D108:$ND108,Rekap!E$6,Absensi!$D$2:$ND$2,$M$2) -> 0 | F110: =COUNTIFS(Absensi!$D108:$ND108,Rekap!F$6,Absensi!$D$2:$ND$2,$M$2) -> 0 | G110: =COUNTIFS(Absensi!$D108:$ND108,Rekap!G$6,Absensi!$D$2:$ND$2,$M$2) -> 0 | H110: =COUNTIFS(Absensi!$D108:$ND108,Rekap!H$6,Absensi!$D$2:$ND$2,$M$2) -> 0 | I110: =COUNTIFS(Absensi!$D108:$ND108,Rekap!I$6,Absensi!$D$2:$ND$2,$M$2) -> 0 | J110: =COUNTIFS(Absensi!$D108:$ND108,Rekap!J$6,Absensi!$D$2:$ND$2,$M$2) -> 0 | M110: =IF($M$2="01",SUMIF(Test!$D:$D,Rekap!D110,Test!$AC:$AC),IF($M$2="02",SUMIF(Test!$D:$D,Rekap!D110,Test!$AD:$AD),IF($M$2="03",SUMIF(Test!$D:$D,Rekap!D110,Test!$AE:$AE),IF($M$2="04",SUMIF(Test!$D:$D,Rekap!D110,Test!$AF:$AF),IF($M$2="05",SUMIF(Test!$D:$D,Rekap!D110,Test!$AG:$AG),IF($M$2="06",SUMIF(Test!$D:$D,Rekap!D110,Test!$AH:$AH),IF($M$2="07",SUMIF(Test!$D:$D,Rekap!D110,Test!$AI:$AI),IF($M$2="08",SUMIF(Test!$D:$D,Rekap!D110,Test!$AJ:$AJ),IF($M$2="09",SUMIF(Test!$D:$D,Rekap!D110,Test!$AK:$AK),IF($M$2="10",SUMIF(Test!$D:$D,Rekap!D110,Test!$AL:$AL),IF($M$2="11",SUMIF(Test!$D:$D,Rekap!D110,Test!$AM:$AM),IF($M$2="12",SUMIF(Test!$D:$D,Rekap!D110,Test!$AN:$AN),0)))))))))))) -> 9
A111: 105 | B111: =Absensi!B109 -> Kebayoran Lama | C111: =Absensi!C109 -> Tri saraswati | D111: =B111&C111 -> Kebayoran LamaTri saraswati | E111: =COUNTIFS(Absensi!$D109:$ND109,Rekap!E$6,Absensi!$D$2:$ND$2,$M$2) -> 0 | F111: =COUNTIFS(Absensi!$D109:$ND109,Rekap!F$6,Absensi!$D$2:$ND$2,$M$2) -> 0 | G111: =COUNTIFS(Absensi!$D109:$ND109,Rekap!G$6,Absensi!$D$2:$ND$2,$M$2) -> 0 | H111: =COUNTIFS(Absensi!$D109:$ND109,Rekap!H$6,Absensi!$D$2:$ND$2,$M$2) -> 0 | I111: =COUNTIFS(Absensi!$D109:$ND109,Rekap!I$6,Absensi!$D$2:$ND$2,$M$2) -> 0 | J111: =COUNTIFS(Absensi!$D109:$ND109,Rekap!J$6,Absensi!$D$2:$ND$2,$M$2) -> 0 | M111: =IF($M$2="01",SUMIF(Test!$D:$D,Rekap!D111,Test!$AC:$AC),IF($M$2="02",SUMIF(Test!$D:$D,Rekap!D111,Test!$AD:$AD),IF($M$2="03",SUMIF(Test!$D:$D,Rekap!D111,Test!$AE:$AE),IF($M$2="04",SUMIF(Test!$D:$D,Rekap!D111,Test!$AF:$AF),IF($M$2="05",SUMIF(Test!$D:$D,Rekap!D111,Test!$AG:$AG),IF($M$2="06",SUMIF(Test!$D:$D,Rekap!D111,Test!$AH:$AH),IF($M$2="07",SUMIF(Test!$D:$D,Rekap!D111,Test!$AI:$AI),IF($M$2="08",SUMIF(Test!$D:$D,Rekap!D111,Test!$AJ:$AJ),IF($M$2="09",SUMIF(Test!$D:$D,Rekap!D111,Test!$AK:$AK),IF($M$2="10",SUMIF(Test!$D:$D,Rekap!D111,Test!$AL:$AL),IF($M$2="11",SUMIF(Test!$D:$D,Rekap!D111,Test!$AM:$AM),IF($M$2="12",SUMIF(Test!$D:$D,Rekap!D111,Test!$AN:$AN),0)))))))))))) -> 9.5
A112: 106 | B112: =Absensi!B110 -> Kebayoran Lama | C112: =Absensi!C110 -> Realita riandy | D112: =B112&C112 -> Kebayoran LamaRealita riandy | E112: =COUNTIFS(Absensi!$D110:$ND110,Rekap!E$6,Absensi!$D$2:$ND$2,$M$2) -> 0 | F112: =COUNTIFS(Absensi!$D110:$ND110,Rekap!F$6,Absensi!$D$2:$ND$2,$M$2) -> 1 | G112: =COUNTIFS(Absensi!$D110:$ND110,Rekap!G$6,Absensi!$D$2:$ND$2,$M$2) -> 0 | H112: =COUNTIFS(Absensi!$D110:$ND110,Rekap!H$6,Absensi!$D$2:$ND$2,$M$2) -> 0 | I112: =COUNTIFS(Absensi!$D110:$ND110,Rekap!I$6,Absensi!$D$2:$ND$2,$M$2) -> 0 | J112: =COUNTIFS(Absensi!$D110:$ND110,Rekap!J$6,Absensi!$D$2:$ND$2,$M$2) -> 0 | M112: =IF($M$2="01",SUMIF(Test!$D:$D,Rekap!D112,Test!$AC:$AC),IF($M$2="02",SUMIF(Test!$D:$D,Rekap!D112,Test!$AD:$AD),IF($M$2="03",SUMIF(Test!$D:$D,Rekap!D112,Test!$AE:$AE),IF($M$2="04",SUMIF(Test!$D:$D,Rekap!D112,Test!$AF:$AF),IF($M$2="05",SUMIF(Test!$D:$D,Rekap!D112,Test!$AG:$AG),IF($M$2="06",SUMIF(Test!$D:$D,Rekap!D112,Test!$AH:$AH),IF($M$2="07",SUMIF(Test!$D:$D,Rekap!D112,Test!$AI:$AI),IF($M$2="08",SUMIF(Test!$D:$D,Rekap!D112,Test!$AJ:$AJ),IF($M$2="09",SUMIF(Test!$D:$D,Rekap!D112,Test!$AK:$AK),IF($M$2="10",SUMIF(Test!$D:$D,Rekap!D112,Test!$AL:$AL),IF($M$2="11",SUMIF(Test!$D:$D,Rekap!D112,Test!$AM:$AM),IF($M$2="12",SUMIF(Test!$D:$D,Rekap!D112,Test!$AN:$AN),0)))))))))))) -> 4
A113: 107 | B113: =Absensi!B111 -> Fishroom | C113: =Absensi!C111 -> Supandi | D113: =B113&C113 -> FishroomSupandi | E113: =COUNTIFS(Absensi!$D111:$ND111,Rekap!E$6,Absensi!$D$2:$ND$2,$M$2) -> 0 | F113: =COUNTIFS(Absensi!$D111:$ND111,Rekap!F$6,Absensi!$D$2:$ND$2,$M$2) -> 0 | G113: =COUNTIFS(Absensi!$D111:$ND111,Rekap!G$6,Absensi!$D$2:$ND$2,$M$2) -> 0 | H113: =COUNTIFS(Absensi!$D111:$ND111,Rekap!H$6,Absensi!$D$2:$ND$2,$M$2) -> 0 | I113: =COUNTIFS(Absensi!$D111:$ND111,Rekap!I$6,Absensi!$D$2:$ND$2,$M$2) -> 0 | J113: =COUNTIFS(Absensi!$D111:$ND111,Rekap!J$6,Absensi!$D$2:$ND$2,$M$2) -> 0 | M113: =IF($M$2="01",SUMIF(Test!$D:$D,Rekap!D113,Test!$AC:$AC),IF($M$2="02",SUMIF(Test!$D:$D,Rekap!D113,Test!$AD:$AD),IF($M$2="03",SUMIF(Test!$D:$D,Rekap!D113,Test!$AE:$AE),IF($M$2="04",SUMIF(Test!$D:$D,Rekap!D113,Test!$AF:$AF),IF($M$2="05",SUMIF(Test!$D:$D,Rekap!D113,Test!$AG:$AG),IF($M$2="06",SUMIF(Test!$D:$D,Rekap!D113,Test!$AH:$AH),IF($M$2="07",SUMIF(Test!$D:$D,Rekap!D113,Test!$AI:$AI),IF($M$2="08",SUMIF(Test!$D:$D,Rekap!D113,Test!$AJ:$AJ),IF($M$2="09",SUMIF(Test!$D:$D,Rekap!D113,Test!$AK:$AK),IF($M$2="10",SUMIF(Test!$D:$D,Rekap!D113,Test!$AL:$AL),IF($M$2="11",SUMIF(Test!$D:$D,Rekap!D113,Test!$AM:$AM),IF($M$2="12",SUMIF(Test!$D:$D,Rekap!D113,Test!$AN:$AN),0)))))))))))) -> -15
A114: 108 | B114: =Absensi!B112 -> Kebayoran Lama | C114: =Absensi!C112 -> Dedi Cahyanto | D114: =B114&C114 -> Kebayoran LamaDedi Cahyanto | E114: =COUNTIFS(Absensi!$D112:$ND112,Rekap!E$6,Absensi!$D$2:$ND$2,$M$2) -> 0 | F114: =COUNTIFS(Absensi!$D112:$ND112,Rekap!F$6,Absensi!$D$2:$ND$2,$M$2) -> 0 | G114: =COUNTIFS(Absensi!$D112:$ND112,Rekap!G$6,Absensi!$D$2:$ND$2,$M$2) -> 0 | H114: =COUNTIFS(Absensi!$D112:$ND112,Rekap!H$6,Absensi!$D$2:$ND$2,$M$2) -> 0 | I114: =COUNTIFS(Absensi!$D112:$ND112,Rekap!I$6,Absensi!$D$2:$ND$2,$M$2) -> 0 | J114: =COUNTIFS(Absensi!$D112:$ND112,Rekap!J$6,Absensi!$D$2:$ND$2,$M$2) -> 0 | M114: =IF($M$2="01",SUMIF(Test!$D:$D,Rekap!D114,Test!$AC:$AC),IF($M$2="02",SUMIF(Test!$D:$D,Rekap!D114,Test!$AD:$AD),IF($M$2="03",SUMIF(Test!$D:$D,Rekap!D114,Test!$AE:$AE),IF($M$2="04",SUMIF(Test!$D:$D,Rekap!D114,Test!$AF:$AF),IF($M$2="05",SUMIF(Test!$D:$D,Rekap!D114,Test!$AG:$AG),IF($M$2="06",SUMIF(Test!$D:$D,Rekap!D114,Test!$AH:$AH),IF($M$2="07",SUMIF(Test!$D:$D,Rekap!D114,Test!$AI:$AI),IF($M$2="08",SUMIF(Test!$D:$D,Rekap!D114,Test!$AJ:$AJ),IF($M$2="09",SUMIF(Test!$D:$D,Rekap!D114,Test!$AK:$AK),IF($M$2="10",SUMIF(Test!$D:$D,Rekap!D114,Test!$AL:$AL),IF($M$2="11",SUMIF(Test!$D:$D,Rekap!D114,Test!$AM:$AM),IF($M$2="12",SUMIF(Test!$D:$D,Rekap!D114,Test!$AN:$AN),0)))))))))))) -> 8
A115: 109 | B115: =Absensi!B113 -> Kebayoran Lama | C115: =Absensi!C113 -> Yulita Fajarini | D115: =B115&C115 -> Kebayoran LamaYulita Fajarini | E115: =COUNTIFS(Absensi!$D113:$ND113,Rekap!E$6,Absensi!$D$2:$ND$2,$M$2) -> 0 | F115: =COUNTIFS(Absensi!$D113:$ND113,Rekap!F$6,Absensi!$D$2:$ND$2,$M$2) -> 0 | G115: =COUNTIFS(Absensi!$D113:$ND113,Rekap!G$6,Absensi!$D$2:$ND$2,$M$2) -> 0 | H115: =COUNTIFS(Absensi!$D113:$ND113,Rekap!H$6,Absensi!$D$2:$ND$2,$M$2) -> 0 | I115: =COUNTIFS(Absensi!$D113:$ND113,Rekap!I$6,Absensi!$D$2:$ND$2,$M$2) -> 0 | J115: =COUNTIFS(Absensi!$D113:$ND113,Rekap!J$6,Absensi!$D$2:$ND$2,$M$2) -> 0 | M115: =IF($M$2="01",SUMIF(Test!$D:$D,Rekap!D115,Test!$AC:$AC),IF($M$2="02",SUMIF(Test!$D:$D,Rekap!D115,Test!$AD:$AD),IF($M$2="03",SUMIF(Test!$D:$D,Rekap!D115,Test!$AE:$AE),IF($M$2="04",SUMIF(Test!$D:$D,Rekap!D115,Test!$AF:$AF),IF($M$2="05",SUMIF(Test!$D:$D,Rekap!D115,Test!$AG:$AG),IF($M$2="06",SUMIF(Test!$D:$D,Rekap!D115,Test!$AH:$AH),IF($M$2="07",SUMIF(Test!$D:$D,Rekap!D115,Test!$AI:$AI),IF($M$2="08",SUMIF(Test!$D:$D,Rekap!D115,Test!$AJ:$AJ),IF($M$2="09",SUMIF(Test!$D:$D,Rekap!D115,Test!$AK:$AK),IF($M$2="10",SUMIF(Test!$D:$D,Rekap!D115,Test!$AL:$AL),IF($M$2="11",SUMIF(Test!$D:$D,Rekap!D115,Test!$AM:$AM),IF($M$2="12",SUMIF(Test!$D:$D,Rekap!D115,Test!$AN:$AN),0)))))))))))) -> 9
A116: 110 | B116: =Absensi!B114 -> Kebayoran Lama | C116: =Absensi!C114 -> Heru Yanuarto | D116: =B116&C116 -> Kebayoran LamaHeru Yanuarto | E116: =COUNTIFS(Absensi!$D114:$ND114,Rekap!E$6,Absensi!$D$2:$ND$2,$M$2) -> 0 | F116: =COUNTIFS(Absensi!$D114:$ND114,Rekap!F$6,Absensi!$D$2:$ND$2,$M$2) -> 0 | G116: =COUNTIFS(Absensi!$D114:$ND114,Rekap!G$6,Absensi!$D$2:$ND$2,$M$2) -> 0 | H116: =COUNTIFS(Absensi!$D114:$ND114,Rekap!H$6,Absensi!$D$2:$ND$2,$M$2) -> 0 | I116: =COUNTIFS(Absensi!$D114:$ND114,Rekap!I$6,Absensi!$D$2:$ND$2,$M$2) -> 0 | J116: =COUNTIFS(Absensi!$D114:$ND114,Rekap!J$6,Absensi!$D$2:$ND$2,$M$2) -> 0 | M116: =IF($M$2="01",SUMIF(Test!$D:$D,Rekap!D116,Test!$AC:$AC),IF($M$2="02",SUMIF(Test!$D:$D,Rekap!D116,Test!$AD:$AD),IF($M$2="03",SUMIF(Test!$D:$D,Rekap!D116,Test!$AE:$AE),IF($M$2="04",SUMIF(Test!$D:$D,Rekap!D116,Test!$AF:$AF),IF($M$2="05",SUMIF(Test!$D:$D,Rekap!D116,Test!$AG:$AG),IF($M$2="06",SUMIF(Test!$D:$D,Rekap!D116,Test!$AH:$AH),IF($M$2="07",SUMIF(Test!$D:$D,Rekap!D116,Test!$AI:$AI),IF($M$2="08",SUMIF(Test!$D:$D,Rekap!D116,Test!$AJ:$AJ),IF($M$2="09",SUMIF(Test!$D:$D,Rekap!D116,Test!$AK:$AK),IF($M$2="10",SUMIF(Test!$D:$D,Rekap!D116,Test!$AL:$AL),IF($M$2="11",SUMIF(Test!$D:$D,Rekap!D116,Test!$AM:$AM),IF($M$2="12",SUMIF(Test!$D:$D,Rekap!D116,Test!$AN:$AN),0)))))))))))) -> 4
A117: 111 | B117: =Absensi!B115 -> Kebayoran Lama | C117: =Absensi!C115 -> Diki Mahendra | D117: =B117&C117 -> Kebayoran LamaDiki Mahendra | E117: =COUNTIFS(Absensi!$D115:$ND115,Rekap!E$6,Absensi!$D$2:$ND$2,$M$2) -> 0 | F117: =COUNTIFS(Absensi!$D115:$ND115,Rekap!F$6,Absensi!$D$2:$ND$2,$M$2) -> 1 | G117: =COUNTIFS(Absensi!$D115:$ND115,Rekap!G$6,Absensi!$D$2:$ND$2,$M$2) -> 0 | H117: =COUNTIFS(Absensi!$D115:$ND115,Rekap!H$6,Absensi!$D$2:$ND$2,$M$2) -> 0 | I117: =COUNTIFS(Absensi!$D115:$ND115,Rekap!I$6,Absensi!$D$2:$ND$2,$M$2) -> 0 | J117: =COUNTIFS(Absensi!$D115:$ND115,Rekap!J$6,Absensi!$D$2:$ND$2,$M$2) -> 0 | M117: =IF($M$2="01",SUMIF(Test!$D:$D,Rekap!D117,Test!$AC:$AC),IF($M$2="02",SUMIF(Test!$D:$D,Rekap!D117,Test!$AD:$AD),IF($M$2="03",SUMIF(Test!$D:$D,Rekap!D117,Test!$AE:$AE),IF($M$2="04",SUMIF(Test!$D:$D,Rekap!D117,Test!$AF:$AF),IF($M$2="05",SUMIF(Test!$D:$D,Rekap!D117,Test!$AG:$AG),IF($M$2="06",SUMIF(Test!$D:$D,Rekap!D117,Test!$AH:$AH),IF($M$2="07",SUMIF(Test!$D:$D,Rekap!D117,Test!$AI:$AI),IF($M$2="08",SUMIF(Test!$D:$D,Rekap!D117,Test!$AJ:$AJ),IF($M$2="09",SUMIF(Test!$D:$D,Rekap!D117,Test!$AK:$AK),IF($M$2="10",SUMIF(Test!$D:$D,Rekap!D117,Test!$AL:$AL),IF($M$2="11",SUMIF(Test!$D:$D,Rekap!D117,Test!$AM:$AM),IF($M$2="12",SUMIF(Test!$D:$D,Rekap!D117,Test!$AN:$AN),0)))))))))))) -> 7
A118: 112 | B118: =Absensi!B116 -> Kebayoran Lama | C118: =Absensi!C116 -> Harry | D118: =B118&C118 -> Kebayoran LamaHarry | E118: =COUNTIFS(Absensi!$D116:$ND116,Rekap!E$6,Absensi!$D$2:$ND$2,$M$2) -> 0 | F118: =COUNTIFS(Absensi!$D116:$ND116,Rekap!F$6,Absensi!$D$2:$ND$2,$M$2) -> 1 | G118: =COUNTIFS(Absensi!$D116:$ND116,Rekap!G$6,Absensi!$D$2:$ND$2,$M$2) -> 0 | H118: =COUNTIFS(Absensi!$D116:$ND116,Rekap!H$6,Absensi!$D$2:$ND$2,$M$2) -> 0 | I118: =COUNTIFS(Absensi!$D116:$ND116,Rekap!I$6,Absensi!$D$2:$ND$2,$M$2) -> 0 | J118: =COUNTIFS(Absensi!$D116:$ND116,Rekap!J$6,Absensi!$D$2:$ND$2,$M$2) -> 0 | M118: =IF($M$2="01",SUMIF(Test!$D:$D,Rekap!D118,Test!$AC:$AC),IF($M$2="02",SUMIF(Test!$D:$D,Rekap!D118,Test!$AD:$AD),IF($M$2="03",SUMIF(Test!$D:$D,Rekap!D118,Test!$AE:$AE),IF($M$2="04",SUMIF(Test!$D:$D,Rekap!D118,Test!$AF:$AF),IF($M$2="05",SUMIF(Test!$D:$D,Rekap!D118,Test!$AG:$AG),IF($M$2="06",SUMIF(Test!$D:$D,Rekap!D118,Test!$AH:$AH),IF($M$2="07",SUMIF(Test!$D:$D,Rekap!D118,Test!$AI:$AI),IF($M$2="08",SUMIF(Test!$D:$D,Rekap!D118,Test!$AJ:$AJ),IF($M$2="09",SUMIF(Test!$D:$D,Rekap!D118,Test!$AK:$AK),IF($M$2="10",SUMIF(Test!$D:$D,Rekap!D118,Test!$AL:$AL),IF($M$2="11",SUMIF(Test!$D:$D,Rekap!D118,Test!$AM:$AM),IF($M$2="12",SUMIF(Test!$D:$D,Rekap!D118,Test!$AN:$AN),0)))))))))))) -> 9
A119: 113 | B119: =Absensi!B117 -> Kebayoran Lama | C119: =Absensi!C117 -> Shella Septiyadis | D119: =B119&C119 -> Kebayoran LamaShella Septiyadis | E119: =COUNTIFS(Absensi!$D117:$ND117,Rekap!E$6,Absensi!$D$2:$ND$2,$M$2) -> 0 | F119: =COUNTIFS(Absensi!$D117:$ND117,Rekap!F$6,Absensi!$D$2:$ND$2,$M$2) -> 0 | G119: =COUNTIFS(Absensi!$D117:$ND117,Rekap!G$6,Absensi!$D$2:$ND$2,$M$2) -> 0 | H119: =COUNTIFS(Absensi!$D117:$ND117,Rekap!H$6,Absensi!$D$2:$ND$2,$M$2) -> 0 | I119: =COUNTIFS(Absensi!$D117:$ND117,Rekap!I$6,Absensi!$D$2:$ND$2,$M$2) -> 0 | J119: =COUNTIFS(Absensi!$D117:$ND117,Rekap!J$6,Absensi!$D$2:$ND$2,$M$2) -> 0 | M119: =IF($M$2="01",SUMIF(Test!$D:$D,Rekap!D119,Test!$AC:$AC),IF($M$2="02",SUMIF(Test!$D:$D,Rekap!D119,Test!$AD:$AD),IF($M$2="03",SUMIF(Test!$D:$D,Rekap!D119,Test!$AE:$AE),IF($M$2="04",SUMIF(Test!$D:$D,Rekap!D119,Test!$AF:$AF),IF($M$2="05",SUMIF(Test!$D:$D,Rekap!D119,Test!$AG:$AG),IF($M$2="06",SUMIF(Test!$D:$D,Rekap!D119,Test!$AH:$AH),IF($M$2="07",SUMIF(Test!$D:$D,Rekap!D119,Test!$AI:$AI),IF($M$2="08",SUMIF(Test!$D:$D,Rekap!D119,Test!$AJ:$AJ),IF($M$2="09",SUMIF(Test!$D:$D,Rekap!D119,Test!$AK:$AK),IF($M$2="10",SUMIF(Test!$D:$D,Rekap!D119,Test!$AL:$AL),IF($M$2="11",SUMIF(Test!$D:$D,Rekap!D119,Test!$AM:$AM),IF($M$2="12",SUMIF(Test!$D:$D,Rekap!D119,Test!$AN:$AN),0)))))))))))) -> 10
A120: 114 | B120: =Absensi!B118 -> Fishroom | C120: =Absensi!C118 -> Sri Fuji Astuti | D120: =B120&C120 -> FishroomSri Fuji Astuti | E120: =COUNTIFS(Absensi!$D118:$ND118,Rekap!E$6,Absensi!$D$2:$ND$2,$M$2) -> 0 | F120: =COUNTIFS(Absensi!$D118:$ND118,Rekap!F$6,Absensi!$D$2:$ND$2,$M$2) -> 1 | G120: =COUNTIFS(Absensi!$D118:$ND118,Rekap!G$6,Absensi!$D$2:$ND$2,$M$2) -> 0 | H120: =COUNTIFS(Absensi!$D118:$ND118,Rekap!H$6,Absensi!$D$2:$ND$2,$M$2) -> 0 | I120: =COUNTIFS(Absensi!$D118:$ND118,Rekap!I$6,Absensi!$D$2:$ND$2,$M$2) -> 0 | J120: =COUNTIFS(Absensi!$D118:$ND118,Rekap!J$6,Absensi!$D$2:$ND$2,$M$2) -> 0 | M120: =IF($M$2="01",SUMIF(Test!$D:$D,Rekap!D120,Test!$AC:$AC),IF($M$2="02",SUMIF(Test!$D:$D,Rekap!D120,Test!$AD:$AD),IF($M$2="03",SUMIF(Test!$D:$D,Rekap!D120,Test!$AE:$AE),IF($M$2="04",SUMIF(Test!$D:$D,Rekap!D120,Test!$AF:$AF),IF($M$2="05",SUMIF(Test!$D:$D,Rekap!D120,Test!$AG:$AG),IF($M$2="06",SUMIF(Test!$D:$D,Rekap!D120,Test!$AH:$AH),IF($M$2="07",SUMIF(Test!$D:$D,Rekap!D120,Test!$AI:$AI),IF($M$2="08",SUMIF(Test!$D:$D,Rekap!D120,Test!$AJ:$AJ),IF($M$2="09",SUMIF(Test!$D:$D,Rekap!D120,Test!$AK:$AK),IF($M$2="10",SUMIF(Test!$D:$D,Rekap!D120,Test!$AL:$AL),IF($M$2="11",SUMIF(Test!$D:$D,Rekap!D120,Test!$AM:$AM),IF($M$2="12",SUMIF(Test!$D:$D,Rekap!D120,Test!$AN:$AN),0)))))))))))) -> 4
... A148: 142 | B148: =Absensi!B146 -> Bandung | C148: =Absensi!C146 -> Rahman Zaenal | D148: =B148&C148 -> BandungRahman Zaenal | E148: =COUNTIFS(Absensi!$D146:$ND146,Rekap!E$6,Absensi!$D$2:$ND$2,$M$2) -> 0 | F148: =COUNTIFS(Absensi!$D146:$ND146,Rekap!F$6,Absensi!$D$2:$ND$2,$M$2) -> 0 | G148: =COUNTIFS(Absensi!$D146:$ND146,Rekap!G$6,Absensi!$D$2:$ND$2,$M$2) -> 0 | H148: =COUNTIFS(Absensi!$D146:$ND146,Rekap!H$6,Absensi!$D$2:$ND$2,$M$2) -> 0 | I148: =COUNTIFS(Absensi!$D146:$ND146,Rekap!I$6,Absensi!$D$2:$ND$2,$M$2) -> 0 | J148: =COUNTIFS(Absensi!$D146:$ND146,Rekap!J$6,Absensi!$D$2:$ND$2,$M$2) -> 0 | M148: =IF($M$2="01",SUMIF(Test!$D:$D,Rekap!D148,Test!$AC:$AC),IF($M$2="02",SUMIF(Test!$D:$D,Rekap!D148,Test!$AD:$AD),IF($M$2="03",SUMIF(Test!$D:$D,Rekap!D148,Test!$AE:$AE),IF($M$2="04",SUMIF(Test!$D:$D,Rekap!D148,Test!$AF:$AF),IF($M$2="05",SUMIF(Test!$D:$D,Rekap!D148,Test!$AG:$AG),IF($M$2="06",SUMIF(Test!$D:$D,Rekap!D148,Test!$AH:$AH),IF($M$2="07",SUMIF(Test!$D:$D,Rekap!D148,Test!$AI:$AI),IF($M$2="08",SUMIF(Test!$D:$D,Rekap!D148,Test!$AJ:$AJ),IF($M$2="09",SUMIF(Test!$D:$D,Rekap!D148,Test!$AK:$AK),IF($M$2="10",SUMIF(Test!$D:$D,Rekap!D148,Test!$AL:$AL),IF($M$2="11",SUMIF(Test!$D:$D,Rekap!D148,Test!$AM:$AM),IF($M$2="12",SUMIF(Test!$D:$D,Rekap!D148,Test!$AN:$AN),0)))))))))))) -> 7
A149: 143 | B149: Set Up | C149: Iwa Kartiwa | D149: =B149&C149 -> Set UpIwa Kartiwa | E149: =COUNTIFS(Absensi!$D147:$ND147,Rekap!E$6,Absensi!$D$2:$ND$2,$M$2) -> 0 | F149: =COUNTIFS(Absensi!$D147:$ND147,Rekap!F$6,Absensi!$D$2:$ND$2,$M$2) -> 0 | G149: =COUNTIFS(Absensi!$D147:$ND147,Rekap!G$6,Absensi!$D$2:$ND$2,$M$2) -> 0 | H149: =COUNTIFS(Absensi!$D147:$ND147,Rekap!H$6,Absensi!$D$2:$ND$2,$M$2) -> 0 | I149: =COUNTIFS(Absensi!$D147:$ND147,Rekap!I$6,Absensi!$D$2:$ND$2,$M$2) -> 0 | J149: =COUNTIFS(Absensi!$D147:$ND147,Rekap!J$6,Absensi!$D$2:$ND$2,$M$2) -> 0 | M149: =IF($M$2="01",SUMIF(Test!$D:$D,Rekap!D149,Test!$AC:$AC),IF($M$2="02",SUMIF(Test!$D:$D,Rekap!D149,Test!$AD:$AD),IF($M$2="03",SUMIF(Test!$D:$D,Rekap!D149,Test!$AE:$AE),IF($M$2="04",SUMIF(Test!$D:$D,Rekap!D149,Test!$AF:$AF),IF($M$2="05",SUMIF(Test!$D:$D,Rekap!D149,Test!$AG:$AG),IF($M$2="06",SUMIF(Test!$D:$D,Rekap!D149,Test!$AH:$AH),IF($M$2="07",SUMIF(Test!$D:$D,Rekap!D149,Test!$AI:$AI),IF($M$2="08",SUMIF(Test!$D:$D,Rekap!D149,Test!$AJ:$AJ),IF($M$2="09",SUMIF(Test!$D:$D,Rekap!D149,Test!$AK:$AK),IF($M$2="10",SUMIF(Test!$D:$D,Rekap!D149,Test!$AL:$AL),IF($M$2="11",SUMIF(Test!$D:$D,Rekap!D149,Test!$AM:$AM),IF($M$2="12",SUMIF(Test!$D:$D,Rekap!D149,Test!$AN:$AN),0)))))))))))) -> 7
A150: 144 | B150: Bandung | C150: Ibnu Gilang Sasongko | D150: =B150&C150 -> BandungIbnu Gilang Sasongko | E150: =COUNTIFS(Absensi!$D148:$ND148,Rekap!E$6,Absensi!$D$2:$ND$2,$M$2) -> 0 | F150: =COUNTIFS(Absensi!$D148:$ND148,Rekap!F$6,Absensi!$D$2:$ND$2,$M$2) -> 0 | G150: =COUNTIFS(Absensi!$D148:$ND148,Rekap!G$6,Absensi!$D$2:$ND$2,$M$2) -> 0 | H150: =COUNTIFS(Absensi!$D148:$ND148,Rekap!H$6,Absensi!$D$2:$ND$2,$M$2) -> 0 | I150: =COUNTIFS(Absensi!$D148:$ND148,Rekap!I$6,Absensi!$D$2:$ND$2,$M$2) -> 0 | J150: =COUNTIFS(Absensi!$D148:$ND148,Rekap!J$6,Absensi!$D$2:$ND$2,$M$2) -> 0 | M150: =IF($M$2="01",SUMIF(Test!$D:$D,Rekap!D150,Test!$AC:$AC),IF($M$2="02",SUMIF(Test!$D:$D,Rekap!D150,Test!$AD:$AD),IF($M$2="03",SUMIF(Test!$D:$D,Rekap!D150,Test!$AE:$AE),IF($M$2="04",SUMIF(Test!$D:$D,Rekap!D150,Test!$AF:$AF),IF($M$2="05",SUMIF(Test!$D:$D,Rekap!D150,Test!$AG:$AG),IF($M$2="06",SUMIF(Test!$D:$D,Rekap!D150,Test!$AH:$AH),IF($M$2="07",SUMIF(Test!$D:$D,Rekap!D150,Test!$AI:$AI),IF($M$2="08",SUMIF(Test!$D:$D,Rekap!D150,Test!$AJ:$AJ),IF($M$2="09",SUMIF(Test!$D:$D,Rekap!D150,Test!$AK:$AK),IF($M$2="10",SUMIF(Test!$D:$D,Rekap!D150,Test!$AL:$AL),IF($M$2="11",SUMIF(Test!$D:$D,Rekap!D150,Test!$AM:$AM),IF($M$2="12",SUMIF(Test!$D:$D,Rekap!D150,Test!$AN:$AN),0)))))))))))) -> 0
D151: =B151&C151
D152: =B152&C152
D153: =B153&C153
D154: =B154&C154
D155: =B155&C155
D156: =B156&C156
...

Sheet Setting
A1: Kode | B1: Keterangan | D1: Bulan | E1: Kode | G1: Tanggal Merah | H1: Hari | I1: Event
A2: H | B2: Hadir | D2: Januari | E2: 01 | G2: 46023 | H2: Kamis | I2: Tahun Baru Masehi
A3: S | B3: Sakit | D3: Februari | E3: 02 | G3: 46038 | H3: Jumat | I3: Isra Mikraj Nabi Muhammad SAW
A4: C | B4: Cuti | D4: Maret | E4: 03 | G4: 46070 | H4: Selasa | I4: Tahun Baru Imlek
A5: T | B5: Terlambat | D5: April | E5: 04 | G5: 46100 | H5: Kamis | I5: Nyepi
A6: KP | B6: Keluar pagi | D6: Mei | E6: 05 | G6: 46102 | H6: Sabtu | I6: Idul Fitri
A7: CS | B7: Cuti Setengah Hari | D7: Juni | E7: 06 | G7: 46103 | H7: Minggu | I7: Idul Fitri
D8: Juli | E8: 07 | G8: 46115 | H8: Jumat | I8: Wafat Yesus Kristus
D9: Agustus | E9: 08 | G9: 46117 | H9: Minggu | I9: Kebangkitan Yesus Kristus (Paskah)
D10: September | E10: 09 | G10: 46143 | H10: Jumat | I10: Hari Buruh Internasional
D11: Oktober | E11: 10 | G11: 46156 | H11: Kamis | I11: Kenaikan Yesus Kristus
D12: November | E12: 11 | G12: 46169 | H12: Rabu | I12: Idul Adha 1447 H
D13: Desember | E13: 12 | G13: 46173 | H13: Minggu | I13: Hari Raya Waisak
G14: 46174 | H14: Senin | I14: Hari Lahir Pancasila
G15: 46189 | H15: Selasa | I15: Tahun Baru Islan 1448 H
G16: 46251 | H16: Senin | I16: Hari Kemerdekaan Indonesia
G17: 46259 | H17: Selasa | I17: Maulid Nabi Muhammad SAW
G18: 46381 | H18: Jumat | I18: Kelahiran Yesus Kristus

Sheet Test
A1: REKAP KEHADIRAN
A5: No. | B5: Nomor Induk Karyawan | C5: Nama Karyawan | E5: CUTI FULL | Q5: CUTI SETENGAH HARI | AC5: SISA CUTI
E6: 01 | F6: 02 | G6: 03 | H6: 04 | I6: 05 | J6: 06 | K6: 07 | L6: 08 | M6: 09 | N6: 10 | O6: 11 | P6: 12 | Q6: 01 | R6: 02 | S6: 03 | T6: 04 | U6: 05 | V6: 06 | W6: 07 | X6: 08 | Y6: 09 | Z6: 10 | AA6: 11 | AB6: 12 | AC6: 01 | AD6: 02 | AE6: 03 | AF6: 04 | AG6: 05 | AH6: 06 | AI6: 07 | AJ6: 08 | AK6: 09 | AL6: 10 | AM6: 11 | AN6: 12
A7: 1 | B7: =Absensi!B5 -> Gudang A | C7: =Rekap!C7 -> Suci Rahmawati | D7: =B7&C7 -> Gudang ASuci Rahmawati | E7: =COUNTIFS(Absensi!$D5:$ND5,"C",Absensi!$D$2:$ND$2,E$6) -> 1 | F7: =COUNTIFS(Absensi!$D5:$ND5,"C",Absensi!$D$2:$ND$2,F$6) -> 1 | G7: =COUNTIFS(Absensi!$D5:$ND5,"C",Absensi!$D$2:$ND$2,G$6) -> 3 | H7: =COUNTIFS(Absensi!$D5:$ND5,"C",Absensi!$D$2:$ND$2,H$6) -> 0 | I7: =COUNTIFS(Absensi!$D5:$ND5,"C",Absensi!$D$2:$ND$2,I$6) -> 0 | J7: =COUNTIFS(Absensi!$D5:$ND5,"C",Absensi!$D$2:$ND$2,J$6) -> 1 | K7: =COUNTIFS(Absensi!$D5:$ND5,"C",Absensi!$D$2:$ND$2,K$6) -> 1 | L7: =COUNTIFS(Absensi!$D5:$ND5,"C",Absensi!$D$2:$ND$2,L$6) -> 1 | ... P7: =COUNTIFS(Absensi!$D5:$ND5,"C",Absensi!$D$2:$ND$2,P$6) -> 0 | Q7: =COUNTIFS(Absensi!$D5:$ND5,"CS",Absensi!$D$2:$ND$2,Q$6) -> 0 | R7: =COUNTIFS(Absensi!$D5:$ND5,"CS",Absensi!$D$2:$ND$2,R$6) -> 0 | S7: =COUNTIFS(Absensi!$D5:$ND5,"CS",Absensi!$D$2:$ND$2,S$6) -> 1 | T7: =COUNTIFS(Absensi!$D5:$ND5,"CS",Absensi!$D$2:$ND$2,T$6) -> 0 | U7: =COUNTIFS(Absensi!$D5:$ND5,"CS",Absensi!$D$2:$ND$2,U$6) -> 0 | V7: =COUNTIFS(Absensi!$D5:$ND5,"CS",Absensi!$D$2:$ND$2,V$6) -> 0 | W7: =COUNTIFS(Absensi!$D5:$ND5,"CS",Absensi!$D$2:$ND$2,W$6) -> 0 | X7: =COUNTIFS(Absensi!$D5:$ND5,"CS",Absensi!$D$2:$ND$2,X$6) -> 0 | ... AB7: =COUNTIFS(Absensi!$D5:$ND5,"CS",Absensi!$D$2:$ND$2,AB$6) -> 0 | AC7: =12-E7-Q7*0.5 -> 11 | AD7: =AC7-F7-R7*0.5 -> 10 | AE7: =AD7-G7-S7*0.5 -> 6.5 | AF7: =AE7-H7-T7*0.5 -> 6.5 | AG7: =AF7-I7-U7*0.5 -> 6.5 | AH7: =AG7-J7-V7*0.5 -> 5.5 | AI7: =AH7-K7-W7*0.5 -> 4.5 | AJ7: =AI7-L7-X7*0.5 -> 3.5 | AK7: =AJ7-M7-Y7*0.5 -> 2.5 | ... AN7: =AM7-P7-AB7*0.5 -> 2.5
A8: 2 | B8: =Absensi!B6 -> Gudang A | C8: =Rekap!C8 -> Nur Octaviani | D8: =B8&C8 -> Gudang ANur Octaviani | E8: =COUNTIFS(Absensi!$D6:$ND6,"C",Absensi!$D$2:$ND$2,E$6) -> 0 | F8: =COUNTIFS(Absensi!$D6:$ND6,"C",Absensi!$D$2:$ND$2,F$6) -> 0 | G8: =COUNTIFS(Absensi!$D6:$ND6,"C",Absensi!$D$2:$ND$2,G$6) -> 2 | H8: =COUNTIFS(Absensi!$D6:$ND6,"C",Absensi!$D$2:$ND$2,H$6) -> 0 | I8: =COUNTIFS(Absensi!$D6:$ND6,"C",Absensi!$D$2:$ND$2,I$6) -> 0 | J8: =COUNTIFS(Absensi!$D6:$ND6,"C",Absensi!$D$2:$ND$2,J$6) -> 0 | K8: =COUNTIFS(Absensi!$D6:$ND6,"C",Absensi!$D$2:$ND$2,K$6) -> 2 | L8: =COUNTIFS(Absensi!$D6:$ND6,"C",Absensi!$D$2:$ND$2,L$6) -> 0 | ... P8: =COUNTIFS(Absensi!$D6:$ND6,"C",Absensi!$D$2:$ND$2,P$6) -> 0 | Q8: =COUNTIFS(Absensi!$D6:$ND6,"CS",Absensi!$D$2:$ND$2,Q$6) -> 0 | R8: =COUNTIFS(Absensi!$D6:$ND6,"CS",Absensi!$D$2:$ND$2,R$6) -> 0 | S8: =COUNTIFS(Absensi!$D6:$ND6,"CS",Absensi!$D$2:$ND$2,S$6) -> 1 | T8: =COUNTIFS(Absensi!$D6:$ND6,"CS",Absensi!$D$2:$ND$2,T$6) -> 0 | U8: =COUNTIFS(Absensi!$D6:$ND6,"CS",Absensi!$D$2:$ND$2,U$6) -> 0 | V8: =COUNTIFS(Absensi!$D6:$ND6,"CS",Absensi!$D$2:$ND$2,V$6) -> 0 | W8: =COUNTIFS(Absensi!$D6:$ND6,"CS",Absensi!$D$2:$ND$2,W$6) -> 1 | X8: =COUNTIFS(Absensi!$D6:$ND6,"CS",Absensi!$D$2:$ND$2,X$6) -> 0 | ... AB8: =COUNTIFS(Absensi!$D6:$ND6,"CS",Absensi!$D$2:$ND$2,AB$6) -> 0 | AC8: =12-E8-Q8*0.5 -> 12 | AD8: =AC8-F8-R8*0.5 -> 12 | AE8: =AD8-G8-S8*0.5 -> 9.5 | AF8: =AE8-H8-T8*0.5 -> 9.5 | AG8: =AF8-I8-U8*0.5 -> 9.5 | AH8: =AG8-J8-V8*0.5 -> 9.5 | AI8: =AH8-K8-W8*0.5 -> 7 | AJ8: =AI8-L8-X8*0.5 -> 7 | AK8: =AJ8-M8-Y8*0.5 -> 6.5 | ... AN8: =AM8-P8-AB8*0.5 -> 6.5
A9: 3 | B9: =Absensi!B7 -> Gudang A | C9: =Rekap!C9 -> M. Farhan | D9: =B9&C9 -> Gudang AM. Farhan | E9: =COUNTIFS(Absensi!$D7:$ND7,"C",Absensi!$D$2:$ND$2,E$6) -> 1 | F9: =COUNTIFS(Absensi!$D7:$ND7,"C",Absensi!$D$2:$ND$2,F$6) -> 0 | G9: =COUNTIFS(Absensi!$D7:$ND7,"C",Absensi!$D$2:$ND$2,G$6) -> 3 | H9: =COUNTIFS(Absensi!$D7:$ND7,"C",Absensi!$D$2:$ND$2,H$6) -> 0 | I9: =COUNTIFS(Absensi!$D7:$ND7,"C",Absensi!$D$2:$ND$2,I$6) -> 0 | J9: =COUNTIFS(Absensi!$D7:$ND7,"C",Absensi!$D$2:$ND$2,J$6) -> 1 | K9: =COUNTIFS(Absensi!$D7:$ND7,"C",Absensi!$D$2:$ND$2,K$6) -> 0 | L9: =COUNTIFS(Absensi!$D7:$ND7,"C",Absensi!$D$2:$ND$2,L$6) -> 3 | ... P9: =COUNTIFS(Absensi!$D7:$ND7,"C",Absensi!$D$2:$ND$2,P$6) -> 0 | Q9: =COUNTIFS(Absensi!$D7:$ND7,"CS",Absensi!$D$2:$ND$2,Q$6) -> 0 | R9: =COUNTIFS(Absensi!$D7:$ND7,"CS",Absensi!$D$2:$ND$2,R$6) -> 0 | S9: =COUNTIFS(Absensi!$D7:$ND7,"CS",Absensi!$D$2:$ND$2,S$6) -> 0 | T9: =COUNTIFS(Absensi!$D7:$ND7,"CS",Absensi!$D$2:$ND$2,T$6) -> 0 | U9: =COUNTIFS(Absensi!$D7:$ND7,"CS",Absensi!$D$2:$ND$2,U$6) -> 0 | V9: =COUNTIFS(Absensi!$D7:$ND7,"CS",Absensi!$D$2:$ND$2,V$6) -> 0 | W9: =COUNTIFS(Absensi!$D7:$ND7,"CS",Absensi!$D$2:$ND$2,W$6) -> 0 | X9: =COUNTIFS(Absensi!$D7:$ND7,"CS",Absensi!$D$2:$ND$2,X$6) -> 0 | ... AB9: =COUNTIFS(Absensi!$D7:$ND7,"CS",Absensi!$D$2:$ND$2,AB$6) -> 0 | AC9: =12-E9-Q9*0.5 -> 11 | AD9: =AC9-F9-R9*0.5 -> 11 | AE9: =AD9-G9-S9*0.5 -> 8 | AF9: =AE9-H9-T9*0.5 -> 8 | AG9: =AF9-I9-U9*0.5 -> 8 | AH9: =AG9-J9-V9*0.5 -> 7 | AI9: =AH9-K9-W9*0.5 -> 7 | AJ9: =AI9-L9-X9*0.5 -> 4 | AK9: =AJ9-M9-Y9*0.5 -> 4 | ... AN9: =AM9-P9-AB9*0.5 -> 4
A10: 4 | B10: =Absensi!B8 -> Gudang A | C10: =Rekap!C10 -> Nadia | D10: =B10&C10 -> Gudang ANadia | E10: =COUNTIFS(Absensi!$D8:$ND8,"C",Absensi!$D$2:$ND$2,E$6) -> 0 | F10: =COUNTIFS(Absensi!$D8:$ND8,"C",Absensi!$D$2:$ND$2,F$6) -> 1 | G10: =COUNTIFS(Absensi!$D8:$ND8,"C",Absensi!$D$2:$ND$2,G$6) -> 5 | H10: =COUNTIFS(Absensi!$D8:$ND8,"C",Absensi!$D$2:$ND$2,H$6) -> 0 | I10: =COUNTIFS(Absensi!$D8:$ND8,"C",Absensi!$D$2:$ND$2,I$6) -> 1 | J10: =COUNTIFS(Absensi!$D8:$ND8,"C",Absensi!$D$2:$ND$2,J$6) -> 0 | K10: =COUNTIFS(Absensi!$D8:$ND8,"C",Absensi!$D$2:$ND$2,K$6) -> 1 | L10: =COUNTIFS(Absensi!$D8:$ND8,"C",Absensi!$D$2:$ND$2,L$6) -> 2 | ... P10: =COUNTIFS(Absensi!$D8:$ND8,"C",Absensi!$D$2:$ND$2,P$6) -> 0 | Q10: =COUNTIFS(Absensi!$D8:$ND8,"CS",Absensi!$D$2:$ND$2,Q$6) -> 0 | R10: =COUNTIFS(Absensi!$D8:$ND8,"CS",Absensi!$D$2:$ND$2,R$6) -> 0 | S10: =COUNTIFS(Absensi!$D8:$ND8,"CS",Absensi!$D$2:$ND$2,S$6) -> 1 | T10: =COUNTIFS(Absensi!$D8:$ND8,"CS",Absensi!$D$2:$ND$2,T$6) -> 0 | U10: =COUNTIFS(Absensi!$D8:$ND8,"CS",Absensi!$D$2:$ND$2,U$6) -> 0 | V10: =COUNTIFS(Absensi!$D8:$ND8,"CS",Absensi!$D$2:$ND$2,V$6) -> 0 | W10: =COUNTIFS(Absensi!$D8:$ND8,"CS",Absensi!$D$2:$ND$2,W$6) -> 0 | X10: =COUNTIFS(Absensi!$D8:$ND8,"CS",Absensi!$D$2:$ND$2,X$6) -> 0 | ... AB10: =COUNTIFS(Absensi!$D8:$ND8,"CS",Absensi!$D$2:$ND$2,AB$6) -> 0 | AC10: =12-E10-Q10*0.5 -> 12 | AD10: =AC10-F10-R10*0.5 -> 11 | AE10: =AD10-G10-S10*0.5 -> 5.5 | AF10: =AE10-H10-T10*0.5 -> 5.5 | AG10: =AF10-I10-U10*0.5 -> 4.5 | AH10: =AG10-J10-V10*0.5 -> 4.5 | AI10: =AH10-K10-W10*0.5 -> 3.5 | AJ10: =AI10-L10-X10*0.5 -> 1.5 | AK10: =AJ10-M10-Y10*0.5 -> 1.5 | ... AN10: =AM10-P10-AB10*0.5 -> 1.5
